Watching for file changes with StatReloader
Not Found: /favicon.ico
Not Found: /favicon.ico
Internal Server Error: /user_profile/user_1/
Traceback (most recent call last):
  File "/home/maria/PycharmProjects/Skillbox/python_django/venv/lib/python3.9/site-packages/django/core/handlers/exception.py", line 55, in inner
    response = get_response(request)
  File "/home/maria/PycharmProjects/Skillbox/python_django/venv/lib/python3.9/site-packages/django/core/handlers/base.py", line 197, in _get_response
    response = wrapped_callback(request, *callback_args, **callback_kwargs)
  File "/home/maria/PycharmProjects/Skillbox/python_django/12_DjangoCaching/djcaching/app_users/views.py", line 64, in user_profile_view
    user = User.objects.get(username=username)
  File "/home/maria/PycharmProjects/Skillbox/python_django/venv/lib/python3.9/site-packages/django/db/models/manager.py", line 85, in manager_method
    return getattr(self.get_queryset(), name)(*args, **kwargs)
  File "/home/maria/PycharmProjects/Skillbox/python_django/venv/lib/python3.9/site-packages/django/db/models/query.py", line 650, in get
    raise self.model.DoesNotExist(
django.contrib.auth.models.User.DoesNotExist: User matching query does not exist.
Not Found: /favicon.ico
Not Found: /favicon.ico
Not Found: /favicon.ico
Not Found: /favicon.ico
Not Found: /favicon.ico
Internal Server Error: /user_profile/user_1/
Traceback (most recent call last):
  File "/home/maria/PycharmProjects/Skillbox/python_django/venv/lib/python3.9/site-packages/django/core/handlers/exception.py", line 55, in inner
    response = get_response(request)
  File "/home/maria/PycharmProjects/Skillbox/python_django/venv/lib/python3.9/site-packages/django/core/handlers/base.py", line 197, in _get_response
    response = wrapped_callback(request, *callback_args, **callback_kwargs)
  File "/home/maria/PycharmProjects/Skillbox/python_django/12_DjangoCaching/djcaching/app_users/views.py", line 64, in user_profile_view
    user = User.objects.get(username=username)
  File "/home/maria/PycharmProjects/Skillbox/python_django/venv/lib/python3.9/site-packages/django/db/models/manager.py", line 85, in manager_method
    return getattr(self.get_queryset(), name)(*args, **kwargs)
  File "/home/maria/PycharmProjects/Skillbox/python_django/venv/lib/python3.9/site-packages/django/db/models/query.py", line 650, in get
    raise self.model.DoesNotExist(
django.contrib.auth.models.User.DoesNotExist: User matching query does not exist.
Not Found: /favicon.ico
/home/maria/PycharmProjects/Skillbox/python_django/12_DjangoCaching/djcaching/app_users/views.py changed, reloading.
Watching for file changes with StatReloader
Not Found: /favicon.ico
Not Found: /favicon.ico
Not Found: /favicon.ico
Not Found: /favicon.ico
Internal Server Error: /user_profile/user_1/
Traceback (most recent call last):
  File "/home/maria/PycharmProjects/Skillbox/python_django/venv/lib/python3.9/site-packages/django/core/handlers/exception.py", line 55, in inner
    response = get_response(request)
  File "/home/maria/PycharmProjects/Skillbox/python_django/venv/lib/python3.9/site-packages/django/core/handlers/base.py", line 197, in _get_response
    response = wrapped_callback(request, *callback_args, **callback_kwargs)
  File "/home/maria/PycharmProjects/Skillbox/python_django/12_DjangoCaching/djcaching/app_users/views.py", line 64, in user_profile_view
    user = User.objects.get(username=username)
  File "/home/maria/PycharmProjects/Skillbox/python_django/venv/lib/python3.9/site-packages/django/db/models/manager.py", line 85, in manager_method
    return getattr(self.get_queryset(), name)(*args, **kwargs)
  File "/home/maria/PycharmProjects/Skillbox/python_django/venv/lib/python3.9/site-packages/django/db/models/query.py", line 650, in get
    raise self.model.DoesNotExist(
django.contrib.auth.models.User.DoesNotExist: User matching query does not exist.
Not Found: /favicon.ico
Not Found: /favicon.ico
Not Found: /favicon.ico
Not Found: /favicon.ico
Not Found: /favicon.ico
Internal Server Error: /user_profile/user_1/
Traceback (most recent call last):
  File "/home/maria/PycharmProjects/Skillbox/python_django/venv/lib/python3.9/site-packages/django/core/handlers/exception.py", line 55, in inner
    response = get_response(request)
  File "/home/maria/PycharmProjects/Skillbox/python_django/venv/lib/python3.9/site-packages/django/core/handlers/base.py", line 197, in _get_response
    response = wrapped_callback(request, *callback_args, **callback_kwargs)
  File "/home/maria/PycharmProjects/Skillbox/python_django/12_DjangoCaching/djcaching/app_users/views.py", line 64, in user_profile_view
    user = User.objects.get(username=username)
  File "/home/maria/PycharmProjects/Skillbox/python_django/venv/lib/python3.9/site-packages/django/db/models/manager.py", line 85, in manager_method
    return getattr(self.get_queryset(), name)(*args, **kwargs)
  File "/home/maria/PycharmProjects/Skillbox/python_django/venv/lib/python3.9/site-packages/django/db/models/query.py", line 650, in get
    raise self.model.DoesNotExist(
django.contrib.auth.models.User.DoesNotExist: User matching query does not exist.
Not Found: /favicon.ico
Internal Server Error: /purchase_confirmed/
Traceback (most recent call last):
  File "/home/maria/PycharmProjects/Skillbox/python_django/venv/lib/python3.9/site-packages/django/core/handlers/exception.py", line 55, in inner
    response = get_response(request)
  File "/home/maria/PycharmProjects/Skillbox/python_django/venv/lib/python3.9/site-packages/django/core/handlers/base.py", line 197, in _get_response
    response = wrapped_callback(request, *callback_args, **callback_kwargs)
  File "/home/maria/PycharmProjects/Skillbox/python_django/12_DjangoCaching/djcaching/app_users/views.py", line 208, in purchase_confirmed_view
    last_order = PurchaseHistoryModel.objects.select_related('orders').first().get(user=request.user)
  File "/home/maria/PycharmProjects/Skillbox/python_django/venv/lib/python3.9/site-packages/django/db/models/query.py", line 1046, in first
    for obj in (self if self.ordered else self.order_by("pk"))[:1]:
  File "/home/maria/PycharmProjects/Skillbox/python_django/venv/lib/python3.9/site-packages/django/db/models/query.py", line 394, in __iter__
    self._fetch_all()
  File "/home/maria/PycharmProjects/Skillbox/python_django/venv/lib/python3.9/site-packages/django/db/models/query.py", line 1866, in _fetch_all
    self._result_cache = list(self._iterable_class(self))
  File "/home/maria/PycharmProjects/Skillbox/python_django/venv/lib/python3.9/site-packages/django/db/models/query.py", line 87, in __iter__
    results = compiler.execute_sql(
  File "/home/maria/PycharmProjects/Skillbox/python_django/venv/lib/python3.9/site-packages/django/db/models/sql/compiler.py", line 1385, in execute_sql
    sql, params = self.as_sql()
  File "/home/maria/PycharmProjects/Skillbox/python_django/venv/lib/python3.9/site-packages/django/db/models/sql/compiler.py", line 593, in as_sql
    extra_select, order_by, group_by = self.pre_sql_setup()
  File "/home/maria/PycharmProjects/Skillbox/python_django/venv/lib/python3.9/site-packages/django/db/models/sql/compiler.py", line 71, in pre_sql_setup
    self.setup_query()
  File "/home/maria/PycharmProjects/Skillbox/python_django/venv/lib/python3.9/site-packages/django/db/models/sql/compiler.py", line 62, in setup_query
    self.select, self.klass_info, self.annotation_col_map = self.get_select()
  File "/home/maria/PycharmProjects/Skillbox/python_django/venv/lib/python3.9/site-packages/django/db/models/sql/compiler.py", line 278, in get_select
    related_klass_infos = self.get_related_selections(select)
  File "/home/maria/PycharmProjects/Skillbox/python_django/venv/lib/python3.9/site-packages/django/db/models/sql/compiler.py", line 1193, in get_related_selections
    raise FieldError(
django.core.exceptions.FieldError: Invalid field name(s) given in select_related: 'orders'. Choices are: user
/home/maria/PycharmProjects/Skillbox/python_django/12_DjangoCaching/djcaching/app_users/views.py changed, reloading.
Watching for file changes with StatReloader
Not Found: /favicon.ico
Not Found: /favicon.ico
Not Found: /favicon.ico
Not Found: /favicon.ico
Internal Server Error: /user_profile/user_1/
Traceback (most recent call last):
  File "/home/maria/PycharmProjects/Skillbox/python_django/venv/lib/python3.9/site-packages/django/core/handlers/exception.py", line 55, in inner
    response = get_response(request)
  File "/home/maria/PycharmProjects/Skillbox/python_django/venv/lib/python3.9/site-packages/django/core/handlers/base.py", line 197, in _get_response
    response = wrapped_callback(request, *callback_args, **callback_kwargs)
  File "/home/maria/PycharmProjects/Skillbox/python_django/12_DjangoCaching/djcaching/app_users/views.py", line 64, in user_profile_view
    user = User.objects.get(username=username)
  File "/home/maria/PycharmProjects/Skillbox/python_django/venv/lib/python3.9/site-packages/django/db/models/manager.py", line 85, in manager_method
    return getattr(self.get_queryset(), name)(*args, **kwargs)
  File "/home/maria/PycharmProjects/Skillbox/python_django/venv/lib/python3.9/site-packages/django/db/models/query.py", line 650, in get
    raise self.model.DoesNotExist(
django.contrib.auth.models.User.DoesNotExist: User matching query does not exist.
Not Found: /favicon.ico
Internal Server Error: /purchase_confirmed/
Traceback (most recent call last):
  File "/home/maria/PycharmProjects/Skillbox/python_django/venv/lib/python3.9/site-packages/django/db/models/fields/__init__.py", line 2018, in get_prep_value
    return int(value)
TypeError: int() argument must be a string, a bytes-like object or a number, not 'SimpleLazyObject'

The above exception was the direct cause of the following exception:

Traceback (most recent call last):
  File "/home/maria/PycharmProjects/Skillbox/python_django/venv/lib/python3.9/site-packages/django/core/handlers/exception.py", line 55, in inner
    response = get_response(request)
  File "/home/maria/PycharmProjects/Skillbox/python_django/venv/lib/python3.9/site-packages/django/core/handlers/base.py", line 197, in _get_response
    response = wrapped_callback(request, *callback_args, **callback_kwargs)
  File "/home/maria/PycharmProjects/Skillbox/python_django/12_DjangoCaching/djcaching/app_users/views.py", line 208, in purchase_confirmed_view
    history = PurchaseHistoryModel.objects.get(user=request.user)
  File "/home/maria/PycharmProjects/Skillbox/python_django/venv/lib/python3.9/site-packages/django/db/models/manager.py", line 85, in manager_method
    return getattr(self.get_queryset(), name)(*args, **kwargs)
  File "/home/maria/PycharmProjects/Skillbox/python_django/venv/lib/python3.9/site-packages/django/db/models/query.py", line 636, in get
    clone = self._chain() if self.query.combinator else self.filter(*args, **kwargs)
  File "/home/maria/PycharmProjects/Skillbox/python_django/venv/lib/python3.9/site-packages/django/db/models/query.py", line 1420, in filter
    return self._filter_or_exclude(False, args, kwargs)
  File "/home/maria/PycharmProjects/Skillbox/python_django/venv/lib/python3.9/site-packages/django/db/models/query.py", line 1438, in _filter_or_exclude
    clone._filter_or_exclude_inplace(negate, args, kwargs)
  File "/home/maria/PycharmProjects/Skillbox/python_django/venv/lib/python3.9/site-packages/django/db/models/query.py", line 1445, in _filter_or_exclude_inplace
    self._query.add_q(Q(*args, **kwargs))
  File "/home/maria/PycharmProjects/Skillbox/python_django/venv/lib/python3.9/site-packages/django/db/models/sql/query.py", line 1532, in add_q
    clause, _ = self._add_q(q_object, self.used_aliases)
  File "/home/maria/PycharmProjects/Skillbox/python_django/venv/lib/python3.9/site-packages/django/db/models/sql/query.py", line 1562, in _add_q
    child_clause, needed_inner = self.build_filter(
  File "/home/maria/PycharmProjects/Skillbox/python_django/venv/lib/python3.9/site-packages/django/db/models/sql/query.py", line 1478, in build_filter
    condition = self.build_lookup(lookups, col, value)
  File "/home/maria/PycharmProjects/Skillbox/python_django/venv/lib/python3.9/site-packages/django/db/models/sql/query.py", line 1303, in build_lookup
    lookup = lookup_class(lhs, rhs)
  File "/home/maria/PycharmProjects/Skillbox/python_django/venv/lib/python3.9/site-packages/django/db/models/lookups.py", line 27, in __init__
    self.rhs = self.get_prep_lookup()
  File "/home/maria/PycharmProjects/Skillbox/python_django/venv/lib/python3.9/site-packages/django/db/models/fields/related_lookups.py", line 166, in get_prep_lookup
    self.rhs = target_field.get_prep_value(self.rhs)
  File "/home/maria/PycharmProjects/Skillbox/python_django/venv/lib/python3.9/site-packages/django/db/models/fields/__init__.py", line 2020, in get_prep_value
    raise e.__class__(
TypeError: Field 'id' expected a number but got <SimpleLazyObject: <django.contrib.auth.models.AnonymousUser object at 0x7f2de25a0f10>>.
Not Found: /favicon.ico
Not Found: /favicon.ico
Not Found: /favicon.ico
Not Found: /favicon.ico
Internal Server Error: /user_profile/user_1/
Traceback (most recent call last):
  File "/home/maria/PycharmProjects/Skillbox/python_django/venv/lib/python3.9/site-packages/django/core/handlers/exception.py", line 55, in inner
    response = get_response(request)
  File "/home/maria/PycharmProjects/Skillbox/python_django/venv/lib/python3.9/site-packages/django/core/handlers/base.py", line 197, in _get_response
    response = wrapped_callback(request, *callback_args, **callback_kwargs)
  File "/home/maria/PycharmProjects/Skillbox/python_django/12_DjangoCaching/djcaching/app_users/views.py", line 64, in user_profile_view
    user = User.objects.get(username=username)
  File "/home/maria/PycharmProjects/Skillbox/python_django/venv/lib/python3.9/site-packages/django/db/models/manager.py", line 85, in manager_method
    return getattr(self.get_queryset(), name)(*args, **kwargs)
  File "/home/maria/PycharmProjects/Skillbox/python_django/venv/lib/python3.9/site-packages/django/db/models/query.py", line 650, in get
    raise self.model.DoesNotExist(
django.contrib.auth.models.User.DoesNotExist: User matching query does not exist.
Not Found: /favicon.ico
Internal Server Error: /purchase_confirmed/
Traceback (most recent call last):
  File "/home/maria/PycharmProjects/Skillbox/python_django/venv/lib/python3.9/site-packages/django/core/handlers/exception.py", line 55, in inner
    response = get_response(request)
  File "/home/maria/PycharmProjects/Skillbox/python_django/venv/lib/python3.9/site-packages/django/core/handlers/base.py", line 197, in _get_response
    response = wrapped_callback(request, *callback_args, **callback_kwargs)
  File "/home/maria/PycharmProjects/Skillbox/python_django/12_DjangoCaching/djcaching/app_users/views.py", line 209, in purchase_confirmed_view
    last_order = OrderModel.object.filter(history=history).first()
AttributeError: type object 'OrderModel' has no attribute 'object'
/home/maria/PycharmProjects/Skillbox/python_django/12_DjangoCaching/djcaching/app_users/views.py changed, reloading.
Watching for file changes with StatReloader
Not Found: /favicon.ico
Not Found: /favicon.ico
Not Found: /favicon.ico
Not Found: /favicon.ico
Internal Server Error: /user_profile/user_1/
Traceback (most recent call last):
  File "/home/maria/PycharmProjects/Skillbox/python_django/venv/lib/python3.9/site-packages/django/core/handlers/exception.py", line 55, in inner
    response = get_response(request)
  File "/home/maria/PycharmProjects/Skillbox/python_django/venv/lib/python3.9/site-packages/django/core/handlers/base.py", line 197, in _get_response
    response = wrapped_callback(request, *callback_args, **callback_kwargs)
  File "/home/maria/PycharmProjects/Skillbox/python_django/12_DjangoCaching/djcaching/app_users/views.py", line 64, in user_profile_view
    user = User.objects.get(username=username)
  File "/home/maria/PycharmProjects/Skillbox/python_django/venv/lib/python3.9/site-packages/django/db/models/manager.py", line 85, in manager_method
    return getattr(self.get_queryset(), name)(*args, **kwargs)
  File "/home/maria/PycharmProjects/Skillbox/python_django/venv/lib/python3.9/site-packages/django/db/models/query.py", line 650, in get
    raise self.model.DoesNotExist(
django.contrib.auth.models.User.DoesNotExist: User matching query does not exist.
Not Found: /favicon.ico
/home/maria/PycharmProjects/Skillbox/python_django/12_DjangoCaching/djcaching/app_users/models.py changed, reloading.
Watching for file changes with StatReloader
/home/maria/PycharmProjects/Skillbox/python_django/12_DjangoCaching/djcaching/app_users/models.py changed, reloading.
Watching for file changes with StatReloader
/home/maria/PycharmProjects/Skillbox/python_django/12_DjangoCaching/djcaching/app_users/models.py changed, reloading.
Watching for file changes with StatReloader
/home/maria/PycharmProjects/Skillbox/python_django/12_DjangoCaching/djcaching/app_users/views.py changed, reloading.
Watching for file changes with StatReloader
/home/maria/PycharmProjects/Skillbox/python_django/12_DjangoCaching/djcaching/app_users/views.py changed, reloading.
Watching for file changes with StatReloader
Not Found: /favicon.ico
Not Found: /favicon.ico
Not Found: /favicon.ico
Not Found: /favicon.ico
Internal Server Error: /user_profile/user_1/
Traceback (most recent call last):
  File "/home/maria/PycharmProjects/Skillbox/python_django/venv/lib/python3.9/site-packages/django/core/handlers/exception.py", line 55, in inner
    response = get_response(request)
  File "/home/maria/PycharmProjects/Skillbox/python_django/venv/lib/python3.9/site-packages/django/core/handlers/base.py", line 197, in _get_response
    response = wrapped_callback(request, *callback_args, **callback_kwargs)
  File "/home/maria/PycharmProjects/Skillbox/python_django/12_DjangoCaching/djcaching/app_users/views.py", line 64, in user_profile_view
    user = User.objects.get(username=username)
  File "/home/maria/PycharmProjects/Skillbox/python_django/venv/lib/python3.9/site-packages/django/db/models/manager.py", line 85, in manager_method
    return getattr(self.get_queryset(), name)(*args, **kwargs)
  File "/home/maria/PycharmProjects/Skillbox/python_django/venv/lib/python3.9/site-packages/django/db/models/query.py", line 650, in get
    raise self.model.DoesNotExist(
django.contrib.auth.models.User.DoesNotExist: User matching query does not exist.
Not Found: /favicon.ico
Internal Server Error: /purchase_confirmed/
Traceback (most recent call last):
  File "/home/maria/PycharmProjects/Skillbox/python_django/venv/lib/python3.9/site-packages/django/db/models/options.py", line 668, in get_field
    return self.fields_map[field_name]
KeyError: 'vendor_code'

During handling of the above exception, another exception occurred:

Traceback (most recent call last):
  File "/home/maria/PycharmProjects/Skillbox/python_django/venv/lib/python3.9/site-packages/django/core/handlers/exception.py", line 55, in inner
    response = get_response(request)
  File "/home/maria/PycharmProjects/Skillbox/python_django/venv/lib/python3.9/site-packages/django/core/handlers/base.py", line 197, in _get_response
    response = wrapped_callback(request, *callback_args, **callback_kwargs)
  File "/home/maria/PycharmProjects/Skillbox/python_django/12_DjangoCaching/djcaching/app_users/views.py", line 209, in purchase_confirmed_view
    last_order = OrderModel.objects.select_related('goods').only('name', 'shop', 'vendor_code').filter(history=history).first()
  File "/home/maria/PycharmProjects/Skillbox/python_django/venv/lib/python3.9/site-packages/django/db/models/query.py", line 1046, in first
    for obj in (self if self.ordered else self.order_by("pk"))[:1]:
  File "/home/maria/PycharmProjects/Skillbox/python_django/venv/lib/python3.9/site-packages/django/db/models/query.py", line 394, in __iter__
    self._fetch_all()
  File "/home/maria/PycharmProjects/Skillbox/python_django/venv/lib/python3.9/site-packages/django/db/models/query.py", line 1866, in _fetch_all
    self._result_cache = list(self._iterable_class(self))
  File "/home/maria/PycharmProjects/Skillbox/python_django/venv/lib/python3.9/site-packages/django/db/models/query.py", line 87, in __iter__
    results = compiler.execute_sql(
  File "/home/maria/PycharmProjects/Skillbox/python_django/venv/lib/python3.9/site-packages/django/db/models/sql/compiler.py", line 1385, in execute_sql
    sql, params = self.as_sql()
  File "/home/maria/PycharmProjects/Skillbox/python_django/venv/lib/python3.9/site-packages/django/db/models/sql/compiler.py", line 593, in as_sql
    extra_select, order_by, group_by = self.pre_sql_setup()
  File "/home/maria/PycharmProjects/Skillbox/python_django/venv/lib/python3.9/site-packages/django/db/models/sql/compiler.py", line 71, in pre_sql_setup
    self.setup_query()
  File "/home/maria/PycharmProjects/Skillbox/python_django/venv/lib/python3.9/site-packages/django/db/models/sql/compiler.py", line 62, in setup_query
    self.select, self.klass_info, self.annotation_col_map = self.get_select()
  File "/home/maria/PycharmProjects/Skillbox/python_django/venv/lib/python3.9/site-packages/django/db/models/sql/compiler.py", line 257, in get_select
    cols = self.get_default_columns()
  File "/home/maria/PycharmProjects/Skillbox/python_django/venv/lib/python3.9/site-packages/django/db/models/sql/compiler.py", line 818, in get_default_columns
    only_load = self.deferred_to_columns()
  File "/home/maria/PycharmProjects/Skillbox/python_django/venv/lib/python3.9/site-packages/django/db/models/sql/compiler.py", line 1316, in deferred_to_columns
    self.query.deferred_to_data(columns)
  File "/home/maria/PycharmProjects/Skillbox/python_django/venv/lib/python3.9/site-packages/django/db/models/sql/query.py", line 758, in deferred_to_data
    field = opts.get_field(parts[-1])
  File "/home/maria/PycharmProjects/Skillbox/python_django/venv/lib/python3.9/site-packages/django/db/models/options.py", line 670, in get_field
    raise FieldDoesNotExist(
django.core.exceptions.FieldDoesNotExist: OrderModel has no field named 'vendor_code'
/home/maria/PycharmProjects/Skillbox/python_django/12_DjangoCaching/djcaching/app_users/views.py changed, reloading.
Watching for file changes with StatReloader
/home/maria/PycharmProjects/Skillbox/python_django/12_DjangoCaching/djcaching/app_users/views.py changed, reloading.
Watching for file changes with StatReloader
Not Found: /favicon.ico
Not Found: /favicon.ico
Not Found: /favicon.ico
Not Found: /favicon.ico
Internal Server Error: /user_profile/user_1/
Traceback (most recent call last):
  File "/home/maria/PycharmProjects/Skillbox/python_django/venv/lib/python3.9/site-packages/django/core/handlers/exception.py", line 55, in inner
    response = get_response(request)
  File "/home/maria/PycharmProjects/Skillbox/python_django/venv/lib/python3.9/site-packages/django/core/handlers/base.py", line 197, in _get_response
    response = wrapped_callback(request, *callback_args, **callback_kwargs)
  File "/home/maria/PycharmProjects/Skillbox/python_django/12_DjangoCaching/djcaching/app_users/views.py", line 64, in user_profile_view
    user = User.objects.get(username=username)
  File "/home/maria/PycharmProjects/Skillbox/python_django/venv/lib/python3.9/site-packages/django/db/models/manager.py", line 85, in manager_method
    return getattr(self.get_queryset(), name)(*args, **kwargs)
  File "/home/maria/PycharmProjects/Skillbox/python_django/venv/lib/python3.9/site-packages/django/db/models/query.py", line 650, in get
    raise self.model.DoesNotExist(
django.contrib.auth.models.User.DoesNotExist: User matching query does not exist.
Not Found: /favicon.ico
Not Found: /favicon.ico
Not Found: /favicon.ico
Not Found: /favicon.ico
Not Found: /favicon.ico
Internal Server Error: /user_profile/user_1/
Traceback (most recent call last):
  File "/home/maria/PycharmProjects/Skillbox/python_django/venv/lib/python3.9/site-packages/django/core/handlers/exception.py", line 55, in inner
    response = get_response(request)
  File "/home/maria/PycharmProjects/Skillbox/python_django/venv/lib/python3.9/site-packages/django/core/handlers/base.py", line 197, in _get_response
    response = wrapped_callback(request, *callback_args, **callback_kwargs)
  File "/home/maria/PycharmProjects/Skillbox/python_django/12_DjangoCaching/djcaching/app_users/views.py", line 64, in user_profile_view
    user = User.objects.get(username=username)
  File "/home/maria/PycharmProjects/Skillbox/python_django/venv/lib/python3.9/site-packages/django/db/models/manager.py", line 85, in manager_method
    return getattr(self.get_queryset(), name)(*args, **kwargs)
  File "/home/maria/PycharmProjects/Skillbox/python_django/venv/lib/python3.9/site-packages/django/db/models/query.py", line 650, in get
    raise self.model.DoesNotExist(
django.contrib.auth.models.User.DoesNotExist: User matching query does not exist.
Not Found: /favicon.ico
Not Found: /favicon.ico
Not Found: /favicon.ico
Not Found: /favicon.ico
Not Found: /favicon.ico
Internal Server Error: /user_profile/user_1/
Traceback (most recent call last):
  File "/home/maria/PycharmProjects/Skillbox/python_django/venv/lib/python3.9/site-packages/django/core/handlers/exception.py", line 55, in inner
    response = get_response(request)
  File "/home/maria/PycharmProjects/Skillbox/python_django/venv/lib/python3.9/site-packages/django/core/handlers/base.py", line 197, in _get_response
    response = wrapped_callback(request, *callback_args, **callback_kwargs)
  File "/home/maria/PycharmProjects/Skillbox/python_django/12_DjangoCaching/djcaching/app_users/views.py", line 64, in user_profile_view
    user = User.objects.get(username=username)
  File "/home/maria/PycharmProjects/Skillbox/python_django/venv/lib/python3.9/site-packages/django/db/models/manager.py", line 85, in manager_method
    return getattr(self.get_queryset(), name)(*args, **kwargs)
  File "/home/maria/PycharmProjects/Skillbox/python_django/venv/lib/python3.9/site-packages/django/db/models/query.py", line 650, in get
    raise self.model.DoesNotExist(
django.contrib.auth.models.User.DoesNotExist: User matching query does not exist.
Not Found: /favicon.ico
Internal Server Error: /purchase_confirmed/
Traceback (most recent call last):
  File "/home/maria/PycharmProjects/Skillbox/python_django/venv/lib/python3.9/site-packages/django/db/models/fields/__init__.py", line 2018, in get_prep_value
    return int(value)
TypeError: int() argument must be a string, a bytes-like object or a number, not 'SimpleLazyObject'

The above exception was the direct cause of the following exception:

Traceback (most recent call last):
  File "/home/maria/PycharmProjects/Skillbox/python_django/venv/lib/python3.9/site-packages/django/core/handlers/exception.py", line 55, in inner
    response = get_response(request)
  File "/home/maria/PycharmProjects/Skillbox/python_django/venv/lib/python3.9/site-packages/django/core/handlers/base.py", line 197, in _get_response
    response = wrapped_callback(request, *callback_args, **callback_kwargs)
  File "/home/maria/PycharmProjects/Skillbox/python_django/12_DjangoCaching/djcaching/app_users/views.py", line 208, in purchase_confirmed_view
    history = PurchaseHistoryModel.objects.get(user=request.user)
  File "/home/maria/PycharmProjects/Skillbox/python_django/venv/lib/python3.9/site-packages/django/db/models/manager.py", line 85, in manager_method
    return getattr(self.get_queryset(), name)(*args, **kwargs)
  File "/home/maria/PycharmProjects/Skillbox/python_django/venv/lib/python3.9/site-packages/django/db/models/query.py", line 636, in get
    clone = self._chain() if self.query.combinator else self.filter(*args, **kwargs)
  File "/home/maria/PycharmProjects/Skillbox/python_django/venv/lib/python3.9/site-packages/django/db/models/query.py", line 1420, in filter
    return self._filter_or_exclude(False, args, kwargs)
  File "/home/maria/PycharmProjects/Skillbox/python_django/venv/lib/python3.9/site-packages/django/db/models/query.py", line 1438, in _filter_or_exclude
    clone._filter_or_exclude_inplace(negate, args, kwargs)
  File "/home/maria/PycharmProjects/Skillbox/python_django/venv/lib/python3.9/site-packages/django/db/models/query.py", line 1445, in _filter_or_exclude_inplace
    self._query.add_q(Q(*args, **kwargs))
  File "/home/maria/PycharmProjects/Skillbox/python_django/venv/lib/python3.9/site-packages/django/db/models/sql/query.py", line 1532, in add_q
    clause, _ = self._add_q(q_object, self.used_aliases)
  File "/home/maria/PycharmProjects/Skillbox/python_django/venv/lib/python3.9/site-packages/django/db/models/sql/query.py", line 1562, in _add_q
    child_clause, needed_inner = self.build_filter(
  File "/home/maria/PycharmProjects/Skillbox/python_django/venv/lib/python3.9/site-packages/django/db/models/sql/query.py", line 1478, in build_filter
    condition = self.build_lookup(lookups, col, value)
  File "/home/maria/PycharmProjects/Skillbox/python_django/venv/lib/python3.9/site-packages/django/db/models/sql/query.py", line 1303, in build_lookup
    lookup = lookup_class(lhs, rhs)
  File "/home/maria/PycharmProjects/Skillbox/python_django/venv/lib/python3.9/site-packages/django/db/models/lookups.py", line 27, in __init__
    self.rhs = self.get_prep_lookup()
  File "/home/maria/PycharmProjects/Skillbox/python_django/venv/lib/python3.9/site-packages/django/db/models/fields/related_lookups.py", line 166, in get_prep_lookup
    self.rhs = target_field.get_prep_value(self.rhs)
  File "/home/maria/PycharmProjects/Skillbox/python_django/venv/lib/python3.9/site-packages/django/db/models/fields/__init__.py", line 2020, in get_prep_value
    raise e.__class__(
TypeError: Field 'id' expected a number but got <SimpleLazyObject: <django.contrib.auth.models.AnonymousUser object at 0x7f9f347a7400>>.
Not Found: /favicon.ico
Not Found: /favicon.ico
Not Found: /favicon.ico
Not Found: /favicon.ico
Internal Server Error: /user_profile/user_1/
Traceback (most recent call last):
  File "/home/maria/PycharmProjects/Skillbox/python_django/venv/lib/python3.9/site-packages/django/core/handlers/exception.py", line 55, in inner
    response = get_response(request)
  File "/home/maria/PycharmProjects/Skillbox/python_django/venv/lib/python3.9/site-packages/django/core/handlers/base.py", line 197, in _get_response
    response = wrapped_callback(request, *callback_args, **callback_kwargs)
  File "/home/maria/PycharmProjects/Skillbox/python_django/12_DjangoCaching/djcaching/app_users/views.py", line 64, in user_profile_view
    user = User.objects.get(username=username)
  File "/home/maria/PycharmProjects/Skillbox/python_django/venv/lib/python3.9/site-packages/django/db/models/manager.py", line 85, in manager_method
    return getattr(self.get_queryset(), name)(*args, **kwargs)
  File "/home/maria/PycharmProjects/Skillbox/python_django/venv/lib/python3.9/site-packages/django/db/models/query.py", line 650, in get
    raise self.model.DoesNotExist(
django.contrib.auth.models.User.DoesNotExist: User matching query does not exist.
Not Found: /favicon.ico
Not Found: /favicon.ico
Not Found: /favicon.ico
Not Found: /favicon.ico
Not Found: /favicon.ico
Internal Server Error: /user_profile/user_1/
Traceback (most recent call last):
  File "/home/maria/PycharmProjects/Skillbox/python_django/venv/lib/python3.9/site-packages/django/core/handlers/exception.py", line 55, in inner
    response = get_response(request)
  File "/home/maria/PycharmProjects/Skillbox/python_django/venv/lib/python3.9/site-packages/django/core/handlers/base.py", line 197, in _get_response
    response = wrapped_callback(request, *callback_args, **callback_kwargs)
  File "/home/maria/PycharmProjects/Skillbox/python_django/12_DjangoCaching/djcaching/app_users/views.py", line 64, in user_profile_view
    user = User.objects.get(username=username)
  File "/home/maria/PycharmProjects/Skillbox/python_django/venv/lib/python3.9/site-packages/django/db/models/manager.py", line 85, in manager_method
    return getattr(self.get_queryset(), name)(*args, **kwargs)
  File "/home/maria/PycharmProjects/Skillbox/python_django/venv/lib/python3.9/site-packages/django/db/models/query.py", line 650, in get
    raise self.model.DoesNotExist(
django.contrib.auth.models.User.DoesNotExist: User matching query does not exist.
Not Found: /favicon.ico
Not Found: /favicon.ico
Not Found: /favicon.ico
Not Found: /favicon.ico
Not Found: /favicon.ico
Internal Server Error: /user_profile/user_1/
Traceback (most recent call last):
  File "/home/maria/PycharmProjects/Skillbox/python_django/venv/lib/python3.9/site-packages/django/core/handlers/exception.py", line 55, in inner
    response = get_response(request)
  File "/home/maria/PycharmProjects/Skillbox/python_django/venv/lib/python3.9/site-packages/django/core/handlers/base.py", line 197, in _get_response
    response = wrapped_callback(request, *callback_args, **callback_kwargs)
  File "/home/maria/PycharmProjects/Skillbox/python_django/12_DjangoCaching/djcaching/app_users/views.py", line 64, in user_profile_view
    user = User.objects.get(username=username)
  File "/home/maria/PycharmProjects/Skillbox/python_django/venv/lib/python3.9/site-packages/django/db/models/manager.py", line 85, in manager_method
    return getattr(self.get_queryset(), name)(*args, **kwargs)
  File "/home/maria/PycharmProjects/Skillbox/python_django/venv/lib/python3.9/site-packages/django/db/models/query.py", line 650, in get
    raise self.model.DoesNotExist(
django.contrib.auth.models.User.DoesNotExist: User matching query does not exist.
Not Found: /favicon.ico
Internal Server Error: /purchase_confirmed/
Traceback (most recent call last):
  File "/home/maria/PycharmProjects/Skillbox/python_django/venv/lib/python3.9/site-packages/django/db/models/fields/__init__.py", line 2018, in get_prep_value
    return int(value)
TypeError: int() argument must be a string, a bytes-like object or a number, not 'SimpleLazyObject'

The above exception was the direct cause of the following exception:

Traceback (most recent call last):
  File "/home/maria/PycharmProjects/Skillbox/python_django/venv/lib/python3.9/site-packages/django/core/handlers/exception.py", line 55, in inner
    response = get_response(request)
  File "/home/maria/PycharmProjects/Skillbox/python_django/venv/lib/python3.9/site-packages/django/core/handlers/base.py", line 197, in _get_response
    response = wrapped_callback(request, *callback_args, **callback_kwargs)
  File "/home/maria/PycharmProjects/Skillbox/python_django/12_DjangoCaching/djcaching/app_users/views.py", line 208, in purchase_confirmed_view
    history = PurchaseHistoryModel.objects.get(user=request.user)
  File "/home/maria/PycharmProjects/Skillbox/python_django/venv/lib/python3.9/site-packages/django/db/models/manager.py", line 85, in manager_method
    return getattr(self.get_queryset(), name)(*args, **kwargs)
  File "/home/maria/PycharmProjects/Skillbox/python_django/venv/lib/python3.9/site-packages/django/db/models/query.py", line 636, in get
    clone = self._chain() if self.query.combinator else self.filter(*args, **kwargs)
  File "/home/maria/PycharmProjects/Skillbox/python_django/venv/lib/python3.9/site-packages/django/db/models/query.py", line 1420, in filter
    return self._filter_or_exclude(False, args, kwargs)
  File "/home/maria/PycharmProjects/Skillbox/python_django/venv/lib/python3.9/site-packages/django/db/models/query.py", line 1438, in _filter_or_exclude
    clone._filter_or_exclude_inplace(negate, args, kwargs)
  File "/home/maria/PycharmProjects/Skillbox/python_django/venv/lib/python3.9/site-packages/django/db/models/query.py", line 1445, in _filter_or_exclude_inplace
    self._query.add_q(Q(*args, **kwargs))
  File "/home/maria/PycharmProjects/Skillbox/python_django/venv/lib/python3.9/site-packages/django/db/models/sql/query.py", line 1532, in add_q
    clause, _ = self._add_q(q_object, self.used_aliases)
  File "/home/maria/PycharmProjects/Skillbox/python_django/venv/lib/python3.9/site-packages/django/db/models/sql/query.py", line 1562, in _add_q
    child_clause, needed_inner = self.build_filter(
  File "/home/maria/PycharmProjects/Skillbox/python_django/venv/lib/python3.9/site-packages/django/db/models/sql/query.py", line 1478, in build_filter
    condition = self.build_lookup(lookups, col, value)
  File "/home/maria/PycharmProjects/Skillbox/python_django/venv/lib/python3.9/site-packages/django/db/models/sql/query.py", line 1303, in build_lookup
    lookup = lookup_class(lhs, rhs)
  File "/home/maria/PycharmProjects/Skillbox/python_django/venv/lib/python3.9/site-packages/django/db/models/lookups.py", line 27, in __init__
    self.rhs = self.get_prep_lookup()
  File "/home/maria/PycharmProjects/Skillbox/python_django/venv/lib/python3.9/site-packages/django/db/models/fields/related_lookups.py", line 166, in get_prep_lookup
    self.rhs = target_field.get_prep_value(self.rhs)
  File "/home/maria/PycharmProjects/Skillbox/python_django/venv/lib/python3.9/site-packages/django/db/models/fields/__init__.py", line 2020, in get_prep_value
    raise e.__class__(
TypeError: Field 'id' expected a number but got <SimpleLazyObject: <django.contrib.auth.models.AnonymousUser object at 0x7fb89a5568b0>>.
Not Found: /favicon.ico
Not Found: /favicon.ico
Not Found: /favicon.ico
Not Found: /favicon.ico
Internal Server Error: /user_profile/user_1/
Traceback (most recent call last):
  File "/home/maria/PycharmProjects/Skillbox/python_django/venv/lib/python3.9/site-packages/django/core/handlers/exception.py", line 55, in inner
    response = get_response(request)
  File "/home/maria/PycharmProjects/Skillbox/python_django/venv/lib/python3.9/site-packages/django/core/handlers/base.py", line 197, in _get_response
    response = wrapped_callback(request, *callback_args, **callback_kwargs)
  File "/home/maria/PycharmProjects/Skillbox/python_django/12_DjangoCaching/djcaching/app_users/views.py", line 64, in user_profile_view
    user = User.objects.get(username=username)
  File "/home/maria/PycharmProjects/Skillbox/python_django/venv/lib/python3.9/site-packages/django/db/models/manager.py", line 85, in manager_method
    return getattr(self.get_queryset(), name)(*args, **kwargs)
  File "/home/maria/PycharmProjects/Skillbox/python_django/venv/lib/python3.9/site-packages/django/db/models/query.py", line 650, in get
    raise self.model.DoesNotExist(
django.contrib.auth.models.User.DoesNotExist: User matching query does not exist.
Not Found: /favicon.ico
/home/maria/PycharmProjects/Skillbox/python_django/12_DjangoCaching/djcaching/app_users/views.py changed, reloading.
Watching for file changes with StatReloader
Not Found: /favicon.ico
Not Found: /favicon.ico
Not Found: /favicon.ico
Not Found: /favicon.ico
Internal Server Error: /user_profile/user_1/
Traceback (most recent call last):
  File "/home/maria/PycharmProjects/Skillbox/python_django/venv/lib/python3.9/site-packages/django/core/handlers/exception.py", line 55, in inner
    response = get_response(request)
  File "/home/maria/PycharmProjects/Skillbox/python_django/venv/lib/python3.9/site-packages/django/core/handlers/base.py", line 197, in _get_response
    response = wrapped_callback(request, *callback_args, **callback_kwargs)
  File "/home/maria/PycharmProjects/Skillbox/python_django/12_DjangoCaching/djcaching/app_users/views.py", line 64, in user_profile_view
    user = User.objects.get(username=username)
  File "/home/maria/PycharmProjects/Skillbox/python_django/venv/lib/python3.9/site-packages/django/db/models/manager.py", line 85, in manager_method
    return getattr(self.get_queryset(), name)(*args, **kwargs)
  File "/home/maria/PycharmProjects/Skillbox/python_django/venv/lib/python3.9/site-packages/django/db/models/query.py", line 650, in get
    raise self.model.DoesNotExist(
django.contrib.auth.models.User.DoesNotExist: User matching query does not exist.
Not Found: /favicon.ico
/home/maria/PycharmProjects/Skillbox/python_django/12_DjangoCaching/djcaching/app_users/views.py changed, reloading.
Watching for file changes with StatReloader
Not Found: /favicon.ico
Not Found: /favicon.ico
Not Found: /favicon.ico
Not Found: /favicon.ico
Internal Server Error: /user_profile/user_1/
Traceback (most recent call last):
  File "/home/maria/PycharmProjects/Skillbox/python_django/venv/lib/python3.9/site-packages/django/core/handlers/exception.py", line 55, in inner
    response = get_response(request)
  File "/home/maria/PycharmProjects/Skillbox/python_django/venv/lib/python3.9/site-packages/django/core/handlers/base.py", line 197, in _get_response
    response = wrapped_callback(request, *callback_args, **callback_kwargs)
  File "/home/maria/PycharmProjects/Skillbox/python_django/12_DjangoCaching/djcaching/app_users/views.py", line 64, in user_profile_view
    user = User.objects.get(username=username)
  File "/home/maria/PycharmProjects/Skillbox/python_django/venv/lib/python3.9/site-packages/django/db/models/manager.py", line 85, in manager_method
    return getattr(self.get_queryset(), name)(*args, **kwargs)
  File "/home/maria/PycharmProjects/Skillbox/python_django/venv/lib/python3.9/site-packages/django/db/models/query.py", line 650, in get
    raise self.model.DoesNotExist(
django.contrib.auth.models.User.DoesNotExist: User matching query does not exist.
Not Found: /favicon.ico
Not Found: /favicon.ico
Not Found: /favicon.ico
Not Found: /favicon.ico
Not Found: /favicon.ico
Internal Server Error: /user_profile/user_1/
Traceback (most recent call last):
  File "/home/maria/PycharmProjects/Skillbox/python_django/venv/lib/python3.9/site-packages/django/core/handlers/exception.py", line 55, in inner
    response = get_response(request)
  File "/home/maria/PycharmProjects/Skillbox/python_django/venv/lib/python3.9/site-packages/django/core/handlers/base.py", line 197, in _get_response
    response = wrapped_callback(request, *callback_args, **callback_kwargs)
  File "/home/maria/PycharmProjects/Skillbox/python_django/12_DjangoCaching/djcaching/app_users/views.py", line 64, in user_profile_view
    user = User.objects.get(username=username)
  File "/home/maria/PycharmProjects/Skillbox/python_django/venv/lib/python3.9/site-packages/django/db/models/manager.py", line 85, in manager_method
    return getattr(self.get_queryset(), name)(*args, **kwargs)
  File "/home/maria/PycharmProjects/Skillbox/python_django/venv/lib/python3.9/site-packages/django/db/models/query.py", line 650, in get
    raise self.model.DoesNotExist(
django.contrib.auth.models.User.DoesNotExist: User matching query does not exist.
Not Found: /favicon.ico
/home/maria/PycharmProjects/Skillbox/python_django/12_DjangoCaching/djcaching/app_users/views.py changed, reloading.
Watching for file changes with StatReloader
Not Found: /favicon.ico
Not Found: /favicon.ico
Not Found: /favicon.ico
Not Found: /favicon.ico
Internal Server Error: /user_profile/user_1/
Traceback (most recent call last):
  File "/home/maria/PycharmProjects/Skillbox/python_django/venv/lib/python3.9/site-packages/django/core/handlers/exception.py", line 55, in inner
    response = get_response(request)
  File "/home/maria/PycharmProjects/Skillbox/python_django/venv/lib/python3.9/site-packages/django/core/handlers/base.py", line 197, in _get_response
    response = wrapped_callback(request, *callback_args, **callback_kwargs)
  File "/home/maria/PycharmProjects/Skillbox/python_django/12_DjangoCaching/djcaching/app_users/views.py", line 64, in user_profile_view
    user = User.objects.get(username=username)
  File "/home/maria/PycharmProjects/Skillbox/python_django/venv/lib/python3.9/site-packages/django/db/models/manager.py", line 85, in manager_method
    return getattr(self.get_queryset(), name)(*args, **kwargs)
  File "/home/maria/PycharmProjects/Skillbox/python_django/venv/lib/python3.9/site-packages/django/db/models/query.py", line 650, in get
    raise self.model.DoesNotExist(
django.contrib.auth.models.User.DoesNotExist: User matching query does not exist.
Not Found: /favicon.ico
/home/maria/PycharmProjects/Skillbox/python_django/12_DjangoCaching/djcaching/app_users/views.py changed, reloading.
Watching for file changes with StatReloader
Not Found: /favicon.ico
Not Found: /favicon.ico
Not Found: /favicon.ico
Not Found: /favicon.ico
Internal Server Error: /user_profile/user_1/
Traceback (most recent call last):
  File "/home/maria/PycharmProjects/Skillbox/python_django/venv/lib/python3.9/site-packages/django/core/handlers/exception.py", line 55, in inner
    response = get_response(request)
  File "/home/maria/PycharmProjects/Skillbox/python_django/venv/lib/python3.9/site-packages/django/core/handlers/base.py", line 197, in _get_response
    response = wrapped_callback(request, *callback_args, **callback_kwargs)
  File "/home/maria/PycharmProjects/Skillbox/python_django/12_DjangoCaching/djcaching/app_users/views.py", line 64, in user_profile_view
    user = User.objects.get(username=username)
  File "/home/maria/PycharmProjects/Skillbox/python_django/venv/lib/python3.9/site-packages/django/db/models/manager.py", line 85, in manager_method
    return getattr(self.get_queryset(), name)(*args, **kwargs)
  File "/home/maria/PycharmProjects/Skillbox/python_django/venv/lib/python3.9/site-packages/django/db/models/query.py", line 650, in get
    raise self.model.DoesNotExist(
django.contrib.auth.models.User.DoesNotExist: User matching query does not exist.
Not Found: /favicon.ico
Not Found: /favicon.ico
Not Found: /favicon.ico
Not Found: /favicon.ico
Not Found: /favicon.ico
Internal Server Error: /user_profile/user_1/
Traceback (most recent call last):
  File "/home/maria/PycharmProjects/Skillbox/python_django/venv/lib/python3.9/site-packages/django/core/handlers/exception.py", line 55, in inner
    response = get_response(request)
  File "/home/maria/PycharmProjects/Skillbox/python_django/venv/lib/python3.9/site-packages/django/core/handlers/base.py", line 197, in _get_response
    response = wrapped_callback(request, *callback_args, **callback_kwargs)
  File "/home/maria/PycharmProjects/Skillbox/python_django/12_DjangoCaching/djcaching/app_users/views.py", line 64, in user_profile_view
    user = User.objects.get(username=username)
  File "/home/maria/PycharmProjects/Skillbox/python_django/venv/lib/python3.9/site-packages/django/db/models/manager.py", line 85, in manager_method
    return getattr(self.get_queryset(), name)(*args, **kwargs)
  File "/home/maria/PycharmProjects/Skillbox/python_django/venv/lib/python3.9/site-packages/django/db/models/query.py", line 650, in get
    raise self.model.DoesNotExist(
django.contrib.auth.models.User.DoesNotExist: User matching query does not exist.
Not Found: /favicon.ico
/home/maria/PycharmProjects/Skillbox/python_django/12_DjangoCaching/djcaching/app_users/views.py changed, reloading.
Watching for file changes with StatReloader
Not Found: /favicon.ico
Not Found: /favicon.ico
Not Found: /favicon.ico
Not Found: /favicon.ico
Internal Server Error: /user_profile/user_1/
Traceback (most recent call last):
  File "/home/maria/PycharmProjects/Skillbox/python_django/venv/lib/python3.9/site-packages/django/core/handlers/exception.py", line 55, in inner
    response = get_response(request)
  File "/home/maria/PycharmProjects/Skillbox/python_django/venv/lib/python3.9/site-packages/django/core/handlers/base.py", line 197, in _get_response
    response = wrapped_callback(request, *callback_args, **callback_kwargs)
  File "/home/maria/PycharmProjects/Skillbox/python_django/12_DjangoCaching/djcaching/app_users/views.py", line 64, in user_profile_view
    user = User.objects.get(username=username)
  File "/home/maria/PycharmProjects/Skillbox/python_django/venv/lib/python3.9/site-packages/django/db/models/manager.py", line 85, in manager_method
    return getattr(self.get_queryset(), name)(*args, **kwargs)
  File "/home/maria/PycharmProjects/Skillbox/python_django/venv/lib/python3.9/site-packages/django/db/models/query.py", line 650, in get
    raise self.model.DoesNotExist(
django.contrib.auth.models.User.DoesNotExist: User matching query does not exist.
Not Found: /favicon.ico
Not Found: /favicon.ico
Not Found: /favicon.ico
Not Found: /favicon.ico
Not Found: /favicon.ico
Internal Server Error: /user_profile/user_1/
Traceback (most recent call last):
  File "/home/maria/PycharmProjects/Skillbox/python_django/venv/lib/python3.9/site-packages/django/core/handlers/exception.py", line 55, in inner
    response = get_response(request)
  File "/home/maria/PycharmProjects/Skillbox/python_django/venv/lib/python3.9/site-packages/django/core/handlers/base.py", line 197, in _get_response
    response = wrapped_callback(request, *callback_args, **callback_kwargs)
  File "/home/maria/PycharmProjects/Skillbox/python_django/12_DjangoCaching/djcaching/app_users/views.py", line 64, in user_profile_view
    user = User.objects.get(username=username)
  File "/home/maria/PycharmProjects/Skillbox/python_django/venv/lib/python3.9/site-packages/django/db/models/manager.py", line 85, in manager_method
    return getattr(self.get_queryset(), name)(*args, **kwargs)
  File "/home/maria/PycharmProjects/Skillbox/python_django/venv/lib/python3.9/site-packages/django/db/models/query.py", line 650, in get
    raise self.model.DoesNotExist(
django.contrib.auth.models.User.DoesNotExist: User matching query does not exist.
Not Found: /favicon.ico
/home/maria/PycharmProjects/Skillbox/python_django/12_DjangoCaching/djcaching/app_users/views.py changed, reloading.
Watching for file changes with StatReloader
Not Found: /favicon.ico
Not Found: /favicon.ico
Not Found: /favicon.ico
Not Found: /favicon.ico
Internal Server Error: /user_profile/user_1/
Traceback (most recent call last):
  File "/home/maria/PycharmProjects/Skillbox/python_django/venv/lib/python3.9/site-packages/django/core/handlers/exception.py", line 55, in inner
    response = get_response(request)
  File "/home/maria/PycharmProjects/Skillbox/python_django/venv/lib/python3.9/site-packages/django/core/handlers/base.py", line 197, in _get_response
    response = wrapped_callback(request, *callback_args, **callback_kwargs)
  File "/home/maria/PycharmProjects/Skillbox/python_django/12_DjangoCaching/djcaching/app_users/views.py", line 64, in user_profile_view
    user = User.objects.get(username=username)
  File "/home/maria/PycharmProjects/Skillbox/python_django/venv/lib/python3.9/site-packages/django/db/models/manager.py", line 85, in manager_method
    return getattr(self.get_queryset(), name)(*args, **kwargs)
  File "/home/maria/PycharmProjects/Skillbox/python_django/venv/lib/python3.9/site-packages/django/db/models/query.py", line 650, in get
    raise self.model.DoesNotExist(
django.contrib.auth.models.User.DoesNotExist: User matching query does not exist.
Not Found: /favicon.ico
/home/maria/PycharmProjects/Skillbox/python_django/12_DjangoCaching/djcaching/app_users/views.py changed, reloading.
Watching for file changes with StatReloader
Not Found: /favicon.ico
Not Found: /favicon.ico
Not Found: /favicon.ico
Not Found: /favicon.ico
Internal Server Error: /user_profile/user_1/
Traceback (most recent call last):
  File "/home/maria/PycharmProjects/Skillbox/python_django/venv/lib/python3.9/site-packages/django/core/handlers/exception.py", line 55, in inner
    response = get_response(request)
  File "/home/maria/PycharmProjects/Skillbox/python_django/venv/lib/python3.9/site-packages/django/core/handlers/base.py", line 197, in _get_response
    response = wrapped_callback(request, *callback_args, **callback_kwargs)
  File "/home/maria/PycharmProjects/Skillbox/python_django/12_DjangoCaching/djcaching/app_users/views.py", line 64, in user_profile_view
    user = User.objects.get(username=username)
  File "/home/maria/PycharmProjects/Skillbox/python_django/venv/lib/python3.9/site-packages/django/db/models/manager.py", line 85, in manager_method
    return getattr(self.get_queryset(), name)(*args, **kwargs)
  File "/home/maria/PycharmProjects/Skillbox/python_django/venv/lib/python3.9/site-packages/django/db/models/query.py", line 650, in get
    raise self.model.DoesNotExist(
django.contrib.auth.models.User.DoesNotExist: User matching query does not exist.
Not Found: /favicon.ico
Not Found: /favicon.ico
Not Found: /favicon.ico
Not Found: /favicon.ico
Not Found: /favicon.ico
Internal Server Error: /user_profile/user_1/
Traceback (most recent call last):
  File "/home/maria/PycharmProjects/Skillbox/python_django/venv/lib/python3.9/site-packages/django/core/handlers/exception.py", line 55, in inner
    response = get_response(request)
  File "/home/maria/PycharmProjects/Skillbox/python_django/venv/lib/python3.9/site-packages/django/core/handlers/base.py", line 197, in _get_response
    response = wrapped_callback(request, *callback_args, **callback_kwargs)
  File "/home/maria/PycharmProjects/Skillbox/python_django/12_DjangoCaching/djcaching/app_users/views.py", line 64, in user_profile_view
    user = User.objects.get(username=username)
  File "/home/maria/PycharmProjects/Skillbox/python_django/venv/lib/python3.9/site-packages/django/db/models/manager.py", line 85, in manager_method
    return getattr(self.get_queryset(), name)(*args, **kwargs)
  File "/home/maria/PycharmProjects/Skillbox/python_django/venv/lib/python3.9/site-packages/django/db/models/query.py", line 650, in get
    raise self.model.DoesNotExist(
django.contrib.auth.models.User.DoesNotExist: User matching query does not exist.
Not Found: /favicon.ico
/home/maria/PycharmProjects/Skillbox/python_django/12_DjangoCaching/djcaching/app_users/views.py changed, reloading.
Watching for file changes with StatReloader
Not Found: /favicon.ico
Not Found: /favicon.ico
Not Found: /favicon.ico
Not Found: /favicon.ico
Internal Server Error: /user_profile/user_1/
Traceback (most recent call last):
  File "/home/maria/PycharmProjects/Skillbox/python_django/venv/lib/python3.9/site-packages/django/core/handlers/exception.py", line 55, in inner
    response = get_response(request)
  File "/home/maria/PycharmProjects/Skillbox/python_django/venv/lib/python3.9/site-packages/django/core/handlers/base.py", line 197, in _get_response
    response = wrapped_callback(request, *callback_args, **callback_kwargs)
  File "/home/maria/PycharmProjects/Skillbox/python_django/12_DjangoCaching/djcaching/app_users/views.py", line 73, in user_profile_view
    history = PurchaseHistoryModel.objects.select_related('orders').get(user=user)
  File "/home/maria/PycharmProjects/Skillbox/python_django/venv/lib/python3.9/site-packages/django/db/models/query.py", line 646, in get
    num = len(clone)
  File "/home/maria/PycharmProjects/Skillbox/python_django/venv/lib/python3.9/site-packages/django/db/models/query.py", line 376, in __len__
    self._fetch_all()
  File "/home/maria/PycharmProjects/Skillbox/python_django/venv/lib/python3.9/site-packages/django/db/models/query.py", line 1866, in _fetch_all
    self._result_cache = list(self._iterable_class(self))
  File "/home/maria/PycharmProjects/Skillbox/python_django/venv/lib/python3.9/site-packages/django/db/models/query.py", line 87, in __iter__
    results = compiler.execute_sql(
  File "/home/maria/PycharmProjects/Skillbox/python_django/venv/lib/python3.9/site-packages/django/db/models/sql/compiler.py", line 1385, in execute_sql
    sql, params = self.as_sql()
  File "/home/maria/PycharmProjects/Skillbox/python_django/venv/lib/python3.9/site-packages/django/db/models/sql/compiler.py", line 593, in as_sql
    extra_select, order_by, group_by = self.pre_sql_setup()
  File "/home/maria/PycharmProjects/Skillbox/python_django/venv/lib/python3.9/site-packages/django/db/models/sql/compiler.py", line 71, in pre_sql_setup
    self.setup_query()
  File "/home/maria/PycharmProjects/Skillbox/python_django/venv/lib/python3.9/site-packages/django/db/models/sql/compiler.py", line 62, in setup_query
    self.select, self.klass_info, self.annotation_col_map = self.get_select()
  File "/home/maria/PycharmProjects/Skillbox/python_django/venv/lib/python3.9/site-packages/django/db/models/sql/compiler.py", line 278, in get_select
    related_klass_infos = self.get_related_selections(select)
  File "/home/maria/PycharmProjects/Skillbox/python_django/venv/lib/python3.9/site-packages/django/db/models/sql/compiler.py", line 1193, in get_related_selections
    raise FieldError(
django.core.exceptions.FieldError: Invalid field name(s) given in select_related: 'orders'. Choices are: user
Internal Server Error: /user_profile/user_1/
Traceback (most recent call last):
  File "/home/maria/PycharmProjects/Skillbox/python_django/venv/lib/python3.9/site-packages/django/core/handlers/exception.py", line 55, in inner
    response = get_response(request)
  File "/home/maria/PycharmProjects/Skillbox/python_django/venv/lib/python3.9/site-packages/django/core/handlers/base.py", line 197, in _get_response
    response = wrapped_callback(request, *callback_args, **callback_kwargs)
  File "/home/maria/PycharmProjects/Skillbox/python_django/12_DjangoCaching/djcaching/app_users/views.py", line 64, in user_profile_view
    user = User.objects.get(username=username)
  File "/home/maria/PycharmProjects/Skillbox/python_django/venv/lib/python3.9/site-packages/django/db/models/manager.py", line 85, in manager_method
    return getattr(self.get_queryset(), name)(*args, **kwargs)
  File "/home/maria/PycharmProjects/Skillbox/python_django/venv/lib/python3.9/site-packages/django/db/models/query.py", line 650, in get
    raise self.model.DoesNotExist(
django.contrib.auth.models.User.DoesNotExist: User matching query does not exist.
Not Found: /favicon.ico
Internal Server Error: /user_profile/user_1/
Traceback (most recent call last):
  File "/home/maria/PycharmProjects/Skillbox/python_django/venv/lib/python3.9/site-packages/django/core/handlers/exception.py", line 55, in inner
    response = get_response(request)
  File "/home/maria/PycharmProjects/Skillbox/python_django/venv/lib/python3.9/site-packages/django/core/handlers/base.py", line 197, in _get_response
    response = wrapped_callback(request, *callback_args, **callback_kwargs)
  File "/home/maria/PycharmProjects/Skillbox/python_django/12_DjangoCaching/djcaching/app_users/views.py", line 73, in user_profile_view
    history = PurchaseHistoryModel.objects.select_related('orders').get(user=user)
  File "/home/maria/PycharmProjects/Skillbox/python_django/venv/lib/python3.9/site-packages/django/db/models/query.py", line 646, in get
    num = len(clone)
  File "/home/maria/PycharmProjects/Skillbox/python_django/venv/lib/python3.9/site-packages/django/db/models/query.py", line 376, in __len__
    self._fetch_all()
  File "/home/maria/PycharmProjects/Skillbox/python_django/venv/lib/python3.9/site-packages/django/db/models/query.py", line 1866, in _fetch_all
    self._result_cache = list(self._iterable_class(self))
  File "/home/maria/PycharmProjects/Skillbox/python_django/venv/lib/python3.9/site-packages/django/db/models/query.py", line 87, in __iter__
    results = compiler.execute_sql(
  File "/home/maria/PycharmProjects/Skillbox/python_django/venv/lib/python3.9/site-packages/django/db/models/sql/compiler.py", line 1385, in execute_sql
    sql, params = self.as_sql()
  File "/home/maria/PycharmProjects/Skillbox/python_django/venv/lib/python3.9/site-packages/django/db/models/sql/compiler.py", line 593, in as_sql
    extra_select, order_by, group_by = self.pre_sql_setup()
  File "/home/maria/PycharmProjects/Skillbox/python_django/venv/lib/python3.9/site-packages/django/db/models/sql/compiler.py", line 71, in pre_sql_setup
    self.setup_query()
  File "/home/maria/PycharmProjects/Skillbox/python_django/venv/lib/python3.9/site-packages/django/db/models/sql/compiler.py", line 62, in setup_query
    self.select, self.klass_info, self.annotation_col_map = self.get_select()
  File "/home/maria/PycharmProjects/Skillbox/python_django/venv/lib/python3.9/site-packages/django/db/models/sql/compiler.py", line 278, in get_select
    related_klass_infos = self.get_related_selections(select)
  File "/home/maria/PycharmProjects/Skillbox/python_django/venv/lib/python3.9/site-packages/django/db/models/sql/compiler.py", line 1193, in get_related_selections
    raise FieldError(
django.core.exceptions.FieldError: Invalid field name(s) given in select_related: 'orders'. Choices are: user
Internal Server Error: /user_profile/user_1/
Traceback (most recent call last):
  File "/home/maria/PycharmProjects/Skillbox/python_django/venv/lib/python3.9/site-packages/django/core/handlers/exception.py", line 55, in inner
    response = get_response(request)
  File "/home/maria/PycharmProjects/Skillbox/python_django/venv/lib/python3.9/site-packages/django/core/handlers/base.py", line 197, in _get_response
    response = wrapped_callback(request, *callback_args, **callback_kwargs)
  File "/home/maria/PycharmProjects/Skillbox/python_django/12_DjangoCaching/djcaching/app_users/views.py", line 73, in user_profile_view
    history = PurchaseHistoryModel.objects.select_related('orders').get(user=user)
  File "/home/maria/PycharmProjects/Skillbox/python_django/venv/lib/python3.9/site-packages/django/db/models/query.py", line 646, in get
    num = len(clone)
  File "/home/maria/PycharmProjects/Skillbox/python_django/venv/lib/python3.9/site-packages/django/db/models/query.py", line 376, in __len__
    self._fetch_all()
  File "/home/maria/PycharmProjects/Skillbox/python_django/venv/lib/python3.9/site-packages/django/db/models/query.py", line 1866, in _fetch_all
    self._result_cache = list(self._iterable_class(self))
  File "/home/maria/PycharmProjects/Skillbox/python_django/venv/lib/python3.9/site-packages/django/db/models/query.py", line 87, in __iter__
    results = compiler.execute_sql(
  File "/home/maria/PycharmProjects/Skillbox/python_django/venv/lib/python3.9/site-packages/django/db/models/sql/compiler.py", line 1385, in execute_sql
    sql, params = self.as_sql()
  File "/home/maria/PycharmProjects/Skillbox/python_django/venv/lib/python3.9/site-packages/django/db/models/sql/compiler.py", line 593, in as_sql
    extra_select, order_by, group_by = self.pre_sql_setup()
  File "/home/maria/PycharmProjects/Skillbox/python_django/venv/lib/python3.9/site-packages/django/db/models/sql/compiler.py", line 71, in pre_sql_setup
    self.setup_query()
  File "/home/maria/PycharmProjects/Skillbox/python_django/venv/lib/python3.9/site-packages/django/db/models/sql/compiler.py", line 62, in setup_query
    self.select, self.klass_info, self.annotation_col_map = self.get_select()
  File "/home/maria/PycharmProjects/Skillbox/python_django/venv/lib/python3.9/site-packages/django/db/models/sql/compiler.py", line 278, in get_select
    related_klass_infos = self.get_related_selections(select)
  File "/home/maria/PycharmProjects/Skillbox/python_django/venv/lib/python3.9/site-packages/django/db/models/sql/compiler.py", line 1193, in get_related_selections
    raise FieldError(
django.core.exceptions.FieldError: Invalid field name(s) given in select_related: 'orders'. Choices are: user
Internal Server Error: /user_profile/user_1/
Traceback (most recent call last):
  File "/home/maria/PycharmProjects/Skillbox/python_django/venv/lib/python3.9/site-packages/django/core/handlers/exception.py", line 55, in inner
    response = get_response(request)
  File "/home/maria/PycharmProjects/Skillbox/python_django/venv/lib/python3.9/site-packages/django/core/handlers/base.py", line 197, in _get_response
    response = wrapped_callback(request, *callback_args, **callback_kwargs)
  File "/home/maria/PycharmProjects/Skillbox/python_django/12_DjangoCaching/djcaching/app_users/views.py", line 73, in user_profile_view
    history = PurchaseHistoryModel.objects.select_related('orders').get(user=user)
  File "/home/maria/PycharmProjects/Skillbox/python_django/venv/lib/python3.9/site-packages/django/db/models/query.py", line 646, in get
    num = len(clone)
  File "/home/maria/PycharmProjects/Skillbox/python_django/venv/lib/python3.9/site-packages/django/db/models/query.py", line 376, in __len__
    self._fetch_all()
  File "/home/maria/PycharmProjects/Skillbox/python_django/venv/lib/python3.9/site-packages/django/db/models/query.py", line 1866, in _fetch_all
    self._result_cache = list(self._iterable_class(self))
  File "/home/maria/PycharmProjects/Skillbox/python_django/venv/lib/python3.9/site-packages/django/db/models/query.py", line 87, in __iter__
    results = compiler.execute_sql(
  File "/home/maria/PycharmProjects/Skillbox/python_django/venv/lib/python3.9/site-packages/django/db/models/sql/compiler.py", line 1385, in execute_sql
    sql, params = self.as_sql()
  File "/home/maria/PycharmProjects/Skillbox/python_django/venv/lib/python3.9/site-packages/django/db/models/sql/compiler.py", line 593, in as_sql
    extra_select, order_by, group_by = self.pre_sql_setup()
  File "/home/maria/PycharmProjects/Skillbox/python_django/venv/lib/python3.9/site-packages/django/db/models/sql/compiler.py", line 71, in pre_sql_setup
    self.setup_query()
  File "/home/maria/PycharmProjects/Skillbox/python_django/venv/lib/python3.9/site-packages/django/db/models/sql/compiler.py", line 62, in setup_query
    self.select, self.klass_info, self.annotation_col_map = self.get_select()
  File "/home/maria/PycharmProjects/Skillbox/python_django/venv/lib/python3.9/site-packages/django/db/models/sql/compiler.py", line 278, in get_select
    related_klass_infos = self.get_related_selections(select)
  File "/home/maria/PycharmProjects/Skillbox/python_django/venv/lib/python3.9/site-packages/django/db/models/sql/compiler.py", line 1193, in get_related_selections
    raise FieldError(
django.core.exceptions.FieldError: Invalid field name(s) given in select_related: 'orders'. Choices are: user
Internal Server Error: /user_profile/user_1/
Traceback (most recent call last):
  File "/home/maria/PycharmProjects/Skillbox/python_django/venv/lib/python3.9/site-packages/django/core/handlers/exception.py", line 55, in inner
    response = get_response(request)
  File "/home/maria/PycharmProjects/Skillbox/python_django/venv/lib/python3.9/site-packages/django/core/handlers/base.py", line 197, in _get_response
    response = wrapped_callback(request, *callback_args, **callback_kwargs)
  File "/home/maria/PycharmProjects/Skillbox/python_django/12_DjangoCaching/djcaching/app_users/views.py", line 73, in user_profile_view
    history = PurchaseHistoryModel.objects.select_related('orders').get(user=user)
  File "/home/maria/PycharmProjects/Skillbox/python_django/venv/lib/python3.9/site-packages/django/db/models/query.py", line 646, in get
    num = len(clone)
  File "/home/maria/PycharmProjects/Skillbox/python_django/venv/lib/python3.9/site-packages/django/db/models/query.py", line 376, in __len__
    self._fetch_all()
  File "/home/maria/PycharmProjects/Skillbox/python_django/venv/lib/python3.9/site-packages/django/db/models/query.py", line 1866, in _fetch_all
    self._result_cache = list(self._iterable_class(self))
  File "/home/maria/PycharmProjects/Skillbox/python_django/venv/lib/python3.9/site-packages/django/db/models/query.py", line 87, in __iter__
    results = compiler.execute_sql(
  File "/home/maria/PycharmProjects/Skillbox/python_django/venv/lib/python3.9/site-packages/django/db/models/sql/compiler.py", line 1385, in execute_sql
    sql, params = self.as_sql()
  File "/home/maria/PycharmProjects/Skillbox/python_django/venv/lib/python3.9/site-packages/django/db/models/sql/compiler.py", line 593, in as_sql
    extra_select, order_by, group_by = self.pre_sql_setup()
  File "/home/maria/PycharmProjects/Skillbox/python_django/venv/lib/python3.9/site-packages/django/db/models/sql/compiler.py", line 71, in pre_sql_setup
    self.setup_query()
  File "/home/maria/PycharmProjects/Skillbox/python_django/venv/lib/python3.9/site-packages/django/db/models/sql/compiler.py", line 62, in setup_query
    self.select, self.klass_info, self.annotation_col_map = self.get_select()
  File "/home/maria/PycharmProjects/Skillbox/python_django/venv/lib/python3.9/site-packages/django/db/models/sql/compiler.py", line 278, in get_select
    related_klass_infos = self.get_related_selections(select)
  File "/home/maria/PycharmProjects/Skillbox/python_django/venv/lib/python3.9/site-packages/django/db/models/sql/compiler.py", line 1193, in get_related_selections
    raise FieldError(
django.core.exceptions.FieldError: Invalid field name(s) given in select_related: 'orders'. Choices are: user
Internal Server Error: /user_profile/user_1/
Traceback (most recent call last):
  File "/home/maria/PycharmProjects/Skillbox/python_django/venv/lib/python3.9/site-packages/django/core/handlers/exception.py", line 55, in inner
    response = get_response(request)
  File "/home/maria/PycharmProjects/Skillbox/python_django/venv/lib/python3.9/site-packages/django/core/handlers/base.py", line 197, in _get_response
    response = wrapped_callback(request, *callback_args, **callback_kwargs)
  File "/home/maria/PycharmProjects/Skillbox/python_django/12_DjangoCaching/djcaching/app_users/views.py", line 73, in user_profile_view
    history = PurchaseHistoryModel.objects.select_related('orders').get(user=user)
  File "/home/maria/PycharmProjects/Skillbox/python_django/venv/lib/python3.9/site-packages/django/db/models/query.py", line 646, in get
    num = len(clone)
  File "/home/maria/PycharmProjects/Skillbox/python_django/venv/lib/python3.9/site-packages/django/db/models/query.py", line 376, in __len__
    self._fetch_all()
  File "/home/maria/PycharmProjects/Skillbox/python_django/venv/lib/python3.9/site-packages/django/db/models/query.py", line 1866, in _fetch_all
    self._result_cache = list(self._iterable_class(self))
  File "/home/maria/PycharmProjects/Skillbox/python_django/venv/lib/python3.9/site-packages/django/db/models/query.py", line 87, in __iter__
    results = compiler.execute_sql(
  File "/home/maria/PycharmProjects/Skillbox/python_django/venv/lib/python3.9/site-packages/django/db/models/sql/compiler.py", line 1385, in execute_sql
    sql, params = self.as_sql()
  File "/home/maria/PycharmProjects/Skillbox/python_django/venv/lib/python3.9/site-packages/django/db/models/sql/compiler.py", line 593, in as_sql
    extra_select, order_by, group_by = self.pre_sql_setup()
  File "/home/maria/PycharmProjects/Skillbox/python_django/venv/lib/python3.9/site-packages/django/db/models/sql/compiler.py", line 71, in pre_sql_setup
    self.setup_query()
  File "/home/maria/PycharmProjects/Skillbox/python_django/venv/lib/python3.9/site-packages/django/db/models/sql/compiler.py", line 62, in setup_query
    self.select, self.klass_info, self.annotation_col_map = self.get_select()
  File "/home/maria/PycharmProjects/Skillbox/python_django/venv/lib/python3.9/site-packages/django/db/models/sql/compiler.py", line 278, in get_select
    related_klass_infos = self.get_related_selections(select)
  File "/home/maria/PycharmProjects/Skillbox/python_django/venv/lib/python3.9/site-packages/django/db/models/sql/compiler.py", line 1193, in get_related_selections
    raise FieldError(
django.core.exceptions.FieldError: Invalid field name(s) given in select_related: 'orders'. Choices are: user
Internal Server Error: /user_profile/user_1/
Traceback (most recent call last):
  File "/home/maria/PycharmProjects/Skillbox/python_django/venv/lib/python3.9/site-packages/django/core/handlers/exception.py", line 55, in inner
    response = get_response(request)
  File "/home/maria/PycharmProjects/Skillbox/python_django/venv/lib/python3.9/site-packages/django/core/handlers/base.py", line 197, in _get_response
    response = wrapped_callback(request, *callback_args, **callback_kwargs)
  File "/home/maria/PycharmProjects/Skillbox/python_django/12_DjangoCaching/djcaching/app_users/views.py", line 73, in user_profile_view
    history = PurchaseHistoryModel.objects.select_related('orders').get(user=user)
  File "/home/maria/PycharmProjects/Skillbox/python_django/venv/lib/python3.9/site-packages/django/db/models/query.py", line 646, in get
    num = len(clone)
  File "/home/maria/PycharmProjects/Skillbox/python_django/venv/lib/python3.9/site-packages/django/db/models/query.py", line 376, in __len__
    self._fetch_all()
  File "/home/maria/PycharmProjects/Skillbox/python_django/venv/lib/python3.9/site-packages/django/db/models/query.py", line 1866, in _fetch_all
    self._result_cache = list(self._iterable_class(self))
  File "/home/maria/PycharmProjects/Skillbox/python_django/venv/lib/python3.9/site-packages/django/db/models/query.py", line 87, in __iter__
    results = compiler.execute_sql(
  File "/home/maria/PycharmProjects/Skillbox/python_django/venv/lib/python3.9/site-packages/django/db/models/sql/compiler.py", line 1385, in execute_sql
    sql, params = self.as_sql()
  File "/home/maria/PycharmProjects/Skillbox/python_django/venv/lib/python3.9/site-packages/django/db/models/sql/compiler.py", line 593, in as_sql
    extra_select, order_by, group_by = self.pre_sql_setup()
  File "/home/maria/PycharmProjects/Skillbox/python_django/venv/lib/python3.9/site-packages/django/db/models/sql/compiler.py", line 71, in pre_sql_setup
    self.setup_query()
  File "/home/maria/PycharmProjects/Skillbox/python_django/venv/lib/python3.9/site-packages/django/db/models/sql/compiler.py", line 62, in setup_query
    self.select, self.klass_info, self.annotation_col_map = self.get_select()
  File "/home/maria/PycharmProjects/Skillbox/python_django/venv/lib/python3.9/site-packages/django/db/models/sql/compiler.py", line 278, in get_select
    related_klass_infos = self.get_related_selections(select)
  File "/home/maria/PycharmProjects/Skillbox/python_django/venv/lib/python3.9/site-packages/django/db/models/sql/compiler.py", line 1193, in get_related_selections
    raise FieldError(
django.core.exceptions.FieldError: Invalid field name(s) given in select_related: 'orders'. Choices are: user
Internal Server Error: /user_profile/user_1/
Traceback (most recent call last):
  File "/home/maria/PycharmProjects/Skillbox/python_django/venv/lib/python3.9/site-packages/django/core/handlers/exception.py", line 55, in inner
    response = get_response(request)
  File "/home/maria/PycharmProjects/Skillbox/python_django/venv/lib/python3.9/site-packages/django/core/handlers/base.py", line 197, in _get_response
    response = wrapped_callback(request, *callback_args, **callback_kwargs)
  File "/home/maria/PycharmProjects/Skillbox/python_django/12_DjangoCaching/djcaching/app_users/views.py", line 73, in user_profile_view
    history = PurchaseHistoryModel.objects.select_related('orders').get(user=user)
  File "/home/maria/PycharmProjects/Skillbox/python_django/venv/lib/python3.9/site-packages/django/db/models/query.py", line 646, in get
    num = len(clone)
  File "/home/maria/PycharmProjects/Skillbox/python_django/venv/lib/python3.9/site-packages/django/db/models/query.py", line 376, in __len__
    self._fetch_all()
  File "/home/maria/PycharmProjects/Skillbox/python_django/venv/lib/python3.9/site-packages/django/db/models/query.py", line 1866, in _fetch_all
    self._result_cache = list(self._iterable_class(self))
  File "/home/maria/PycharmProjects/Skillbox/python_django/venv/lib/python3.9/site-packages/django/db/models/query.py", line 87, in __iter__
    results = compiler.execute_sql(
  File "/home/maria/PycharmProjects/Skillbox/python_django/venv/lib/python3.9/site-packages/django/db/models/sql/compiler.py", line 1385, in execute_sql
    sql, params = self.as_sql()
  File "/home/maria/PycharmProjects/Skillbox/python_django/venv/lib/python3.9/site-packages/django/db/models/sql/compiler.py", line 593, in as_sql
    extra_select, order_by, group_by = self.pre_sql_setup()
  File "/home/maria/PycharmProjects/Skillbox/python_django/venv/lib/python3.9/site-packages/django/db/models/sql/compiler.py", line 71, in pre_sql_setup
    self.setup_query()
  File "/home/maria/PycharmProjects/Skillbox/python_django/venv/lib/python3.9/site-packages/django/db/models/sql/compiler.py", line 62, in setup_query
    self.select, self.klass_info, self.annotation_col_map = self.get_select()
  File "/home/maria/PycharmProjects/Skillbox/python_django/venv/lib/python3.9/site-packages/django/db/models/sql/compiler.py", line 278, in get_select
    related_klass_infos = self.get_related_selections(select)
  File "/home/maria/PycharmProjects/Skillbox/python_django/venv/lib/python3.9/site-packages/django/db/models/sql/compiler.py", line 1193, in get_related_selections
    raise FieldError(
django.core.exceptions.FieldError: Invalid field name(s) given in select_related: 'orders'. Choices are: user
Internal Server Error: /user_profile/user_1/
Traceback (most recent call last):
  File "/home/maria/PycharmProjects/Skillbox/python_django/venv/lib/python3.9/site-packages/django/core/handlers/exception.py", line 55, in inner
    response = get_response(request)
  File "/home/maria/PycharmProjects/Skillbox/python_django/venv/lib/python3.9/site-packages/django/core/handlers/base.py", line 197, in _get_response
    response = wrapped_callback(request, *callback_args, **callback_kwargs)
  File "/home/maria/PycharmProjects/Skillbox/python_django/12_DjangoCaching/djcaching/app_users/views.py", line 73, in user_profile_view
    history = PurchaseHistoryModel.objects.select_related('orders').get(user=user)
  File "/home/maria/PycharmProjects/Skillbox/python_django/venv/lib/python3.9/site-packages/django/db/models/query.py", line 646, in get
    num = len(clone)
  File "/home/maria/PycharmProjects/Skillbox/python_django/venv/lib/python3.9/site-packages/django/db/models/query.py", line 376, in __len__
    self._fetch_all()
  File "/home/maria/PycharmProjects/Skillbox/python_django/venv/lib/python3.9/site-packages/django/db/models/query.py", line 1866, in _fetch_all
    self._result_cache = list(self._iterable_class(self))
  File "/home/maria/PycharmProjects/Skillbox/python_django/venv/lib/python3.9/site-packages/django/db/models/query.py", line 87, in __iter__
    results = compiler.execute_sql(
  File "/home/maria/PycharmProjects/Skillbox/python_django/venv/lib/python3.9/site-packages/django/db/models/sql/compiler.py", line 1385, in execute_sql
    sql, params = self.as_sql()
  File "/home/maria/PycharmProjects/Skillbox/python_django/venv/lib/python3.9/site-packages/django/db/models/sql/compiler.py", line 593, in as_sql
    extra_select, order_by, group_by = self.pre_sql_setup()
  File "/home/maria/PycharmProjects/Skillbox/python_django/venv/lib/python3.9/site-packages/django/db/models/sql/compiler.py", line 71, in pre_sql_setup
    self.setup_query()
  File "/home/maria/PycharmProjects/Skillbox/python_django/venv/lib/python3.9/site-packages/django/db/models/sql/compiler.py", line 62, in setup_query
    self.select, self.klass_info, self.annotation_col_map = self.get_select()
  File "/home/maria/PycharmProjects/Skillbox/python_django/venv/lib/python3.9/site-packages/django/db/models/sql/compiler.py", line 278, in get_select
    related_klass_infos = self.get_related_selections(select)
  File "/home/maria/PycharmProjects/Skillbox/python_django/venv/lib/python3.9/site-packages/django/db/models/sql/compiler.py", line 1193, in get_related_selections
    raise FieldError(
django.core.exceptions.FieldError: Invalid field name(s) given in select_related: 'orders'. Choices are: user
Internal Server Error: /user_profile/user_1/
Traceback (most recent call last):
  File "/home/maria/PycharmProjects/Skillbox/python_django/venv/lib/python3.9/site-packages/django/core/handlers/exception.py", line 55, in inner
    response = get_response(request)
  File "/home/maria/PycharmProjects/Skillbox/python_django/venv/lib/python3.9/site-packages/django/core/handlers/base.py", line 197, in _get_response
    response = wrapped_callback(request, *callback_args, **callback_kwargs)
  File "/home/maria/PycharmProjects/Skillbox/python_django/12_DjangoCaching/djcaching/app_users/views.py", line 73, in user_profile_view
    history = PurchaseHistoryModel.objects.select_related('orders').get(user=user)
  File "/home/maria/PycharmProjects/Skillbox/python_django/venv/lib/python3.9/site-packages/django/db/models/query.py", line 646, in get
    num = len(clone)
  File "/home/maria/PycharmProjects/Skillbox/python_django/venv/lib/python3.9/site-packages/django/db/models/query.py", line 376, in __len__
    self._fetch_all()
  File "/home/maria/PycharmProjects/Skillbox/python_django/venv/lib/python3.9/site-packages/django/db/models/query.py", line 1866, in _fetch_all
    self._result_cache = list(self._iterable_class(self))
  File "/home/maria/PycharmProjects/Skillbox/python_django/venv/lib/python3.9/site-packages/django/db/models/query.py", line 87, in __iter__
    results = compiler.execute_sql(
  File "/home/maria/PycharmProjects/Skillbox/python_django/venv/lib/python3.9/site-packages/django/db/models/sql/compiler.py", line 1385, in execute_sql
    sql, params = self.as_sql()
  File "/home/maria/PycharmProjects/Skillbox/python_django/venv/lib/python3.9/site-packages/django/db/models/sql/compiler.py", line 593, in as_sql
    extra_select, order_by, group_by = self.pre_sql_setup()
  File "/home/maria/PycharmProjects/Skillbox/python_django/venv/lib/python3.9/site-packages/django/db/models/sql/compiler.py", line 71, in pre_sql_setup
    self.setup_query()
  File "/home/maria/PycharmProjects/Skillbox/python_django/venv/lib/python3.9/site-packages/django/db/models/sql/compiler.py", line 62, in setup_query
    self.select, self.klass_info, self.annotation_col_map = self.get_select()
  File "/home/maria/PycharmProjects/Skillbox/python_django/venv/lib/python3.9/site-packages/django/db/models/sql/compiler.py", line 278, in get_select
    related_klass_infos = self.get_related_selections(select)
  File "/home/maria/PycharmProjects/Skillbox/python_django/venv/lib/python3.9/site-packages/django/db/models/sql/compiler.py", line 1193, in get_related_selections
    raise FieldError(
django.core.exceptions.FieldError: Invalid field name(s) given in select_related: 'orders'. Choices are: user
Internal Server Error: /user_profile/user_1/
Traceback (most recent call last):
  File "/home/maria/PycharmProjects/Skillbox/python_django/venv/lib/python3.9/site-packages/django/core/handlers/exception.py", line 55, in inner
    response = get_response(request)
  File "/home/maria/PycharmProjects/Skillbox/python_django/venv/lib/python3.9/site-packages/django/core/handlers/base.py", line 197, in _get_response
    response = wrapped_callback(request, *callback_args, **callback_kwargs)
  File "/home/maria/PycharmProjects/Skillbox/python_django/12_DjangoCaching/djcaching/app_users/views.py", line 73, in user_profile_view
    history = PurchaseHistoryModel.objects.select_related('orders').get(user=user)
  File "/home/maria/PycharmProjects/Skillbox/python_django/venv/lib/python3.9/site-packages/django/db/models/query.py", line 646, in get
    num = len(clone)
  File "/home/maria/PycharmProjects/Skillbox/python_django/venv/lib/python3.9/site-packages/django/db/models/query.py", line 376, in __len__
    self._fetch_all()
  File "/home/maria/PycharmProjects/Skillbox/python_django/venv/lib/python3.9/site-packages/django/db/models/query.py", line 1866, in _fetch_all
    self._result_cache = list(self._iterable_class(self))
  File "/home/maria/PycharmProjects/Skillbox/python_django/venv/lib/python3.9/site-packages/django/db/models/query.py", line 87, in __iter__
    results = compiler.execute_sql(
  File "/home/maria/PycharmProjects/Skillbox/python_django/venv/lib/python3.9/site-packages/django/db/models/sql/compiler.py", line 1385, in execute_sql
    sql, params = self.as_sql()
  File "/home/maria/PycharmProjects/Skillbox/python_django/venv/lib/python3.9/site-packages/django/db/models/sql/compiler.py", line 593, in as_sql
    extra_select, order_by, group_by = self.pre_sql_setup()
  File "/home/maria/PycharmProjects/Skillbox/python_django/venv/lib/python3.9/site-packages/django/db/models/sql/compiler.py", line 71, in pre_sql_setup
    self.setup_query()
  File "/home/maria/PycharmProjects/Skillbox/python_django/venv/lib/python3.9/site-packages/django/db/models/sql/compiler.py", line 62, in setup_query
    self.select, self.klass_info, self.annotation_col_map = self.get_select()
  File "/home/maria/PycharmProjects/Skillbox/python_django/venv/lib/python3.9/site-packages/django/db/models/sql/compiler.py", line 278, in get_select
    related_klass_infos = self.get_related_selections(select)
  File "/home/maria/PycharmProjects/Skillbox/python_django/venv/lib/python3.9/site-packages/django/db/models/sql/compiler.py", line 1193, in get_related_selections
    raise FieldError(
django.core.exceptions.FieldError: Invalid field name(s) given in select_related: 'orders'. Choices are: user
/home/maria/PycharmProjects/Skillbox/python_django/12_DjangoCaching/djcaching/app_users/views.py changed, reloading.
Watching for file changes with StatReloader
Not Found: /favicon.ico
Not Found: /favicon.ico
Not Found: /favicon.ico
Not Found: /favicon.ico
Internal Server Error: /user_profile/user_1/
Traceback (most recent call last):
  File "/home/maria/PycharmProjects/Skillbox/python_django/venv/lib/python3.9/site-packages/django/core/handlers/exception.py", line 55, in inner
    response = get_response(request)
  File "/home/maria/PycharmProjects/Skillbox/python_django/venv/lib/python3.9/site-packages/django/core/handlers/base.py", line 197, in _get_response
    response = wrapped_callback(request, *callback_args, **callback_kwargs)
  File "/home/maria/PycharmProjects/Skillbox/python_django/12_DjangoCaching/djcaching/app_users/views.py", line 64, in user_profile_view
    user = User.objects.get(username=username)
  File "/home/maria/PycharmProjects/Skillbox/python_django/venv/lib/python3.9/site-packages/django/db/models/manager.py", line 85, in manager_method
    return getattr(self.get_queryset(), name)(*args, **kwargs)
  File "/home/maria/PycharmProjects/Skillbox/python_django/venv/lib/python3.9/site-packages/django/db/models/query.py", line 650, in get
    raise self.model.DoesNotExist(
django.contrib.auth.models.User.DoesNotExist: User matching query does not exist.
Not Found: /favicon.ico
/home/maria/PycharmProjects/Skillbox/python_django/12_DjangoCaching/djcaching/app_users/views.py changed, reloading.
Watching for file changes with StatReloader
/home/maria/PycharmProjects/Skillbox/python_django/12_DjangoCaching/djcaching/app_users/views.py changed, reloading.
Watching for file changes with StatReloader
Not Found: /favicon.ico
Not Found: /favicon.ico
Not Found: /favicon.ico
Not Found: /favicon.ico
Internal Server Error: /user_profile/user_1/
Traceback (most recent call last):
  File "/home/maria/PycharmProjects/Skillbox/python_django/venv/lib/python3.9/site-packages/django/core/handlers/exception.py", line 55, in inner
    response = get_response(request)
  File "/home/maria/PycharmProjects/Skillbox/python_django/venv/lib/python3.9/site-packages/django/core/handlers/base.py", line 197, in _get_response
    response = wrapped_callback(request, *callback_args, **callback_kwargs)
  File "/home/maria/PycharmProjects/Skillbox/python_django/12_DjangoCaching/djcaching/app_users/views.py", line 64, in user_profile_view
    user = User.objects.get(username=username)
  File "/home/maria/PycharmProjects/Skillbox/python_django/venv/lib/python3.9/site-packages/django/db/models/manager.py", line 85, in manager_method
    return getattr(self.get_queryset(), name)(*args, **kwargs)
  File "/home/maria/PycharmProjects/Skillbox/python_django/venv/lib/python3.9/site-packages/django/db/models/query.py", line 650, in get
    raise self.model.DoesNotExist(
django.contrib.auth.models.User.DoesNotExist: User matching query does not exist.
Not Found: /favicon.ico
/home/maria/PycharmProjects/Skillbox/python_django/12_DjangoCaching/djcaching/app_users/views.py changed, reloading.
Watching for file changes with StatReloader
Not Found: /favicon.ico
Not Found: /favicon.ico
Not Found: /favicon.ico
Not Found: /favicon.ico
Internal Server Error: /user_profile/user_1/
Traceback (most recent call last):
  File "/home/maria/PycharmProjects/Skillbox/python_django/venv/lib/python3.9/site-packages/django/core/handlers/exception.py", line 55, in inner
    response = get_response(request)
  File "/home/maria/PycharmProjects/Skillbox/python_django/venv/lib/python3.9/site-packages/django/core/handlers/base.py", line 197, in _get_response
    response = wrapped_callback(request, *callback_args, **callback_kwargs)
  File "/home/maria/PycharmProjects/Skillbox/python_django/12_DjangoCaching/djcaching/app_users/views.py", line 64, in user_profile_view
    user = User.objects.get(username=username)
  File "/home/maria/PycharmProjects/Skillbox/python_django/venv/lib/python3.9/site-packages/django/db/models/manager.py", line 85, in manager_method
    return getattr(self.get_queryset(), name)(*args, **kwargs)
  File "/home/maria/PycharmProjects/Skillbox/python_django/venv/lib/python3.9/site-packages/django/db/models/query.py", line 650, in get
    raise self.model.DoesNotExist(
django.contrib.auth.models.User.DoesNotExist: User matching query does not exist.
Not Found: /favicon.ico
/home/maria/PycharmProjects/Skillbox/python_django/12_DjangoCaching/djcaching/app_users/views.py changed, reloading.
Watching for file changes with StatReloader
Not Found: /favicon.ico
Not Found: /favicon.ico
Not Found: /favicon.ico
Not Found: /favicon.ico
Internal Server Error: /user_profile/user_1/
Traceback (most recent call last):
  File "/home/maria/PycharmProjects/Skillbox/python_django/venv/lib/python3.9/site-packages/django/core/handlers/exception.py", line 55, in inner
    response = get_response(request)
  File "/home/maria/PycharmProjects/Skillbox/python_django/venv/lib/python3.9/site-packages/django/core/handlers/base.py", line 197, in _get_response
    response = wrapped_callback(request, *callback_args, **callback_kwargs)
  File "/home/maria/PycharmProjects/Skillbox/python_django/12_DjangoCaching/djcaching/app_users/views.py", line 64, in user_profile_view
    user = User.objects.get(username=username)
  File "/home/maria/PycharmProjects/Skillbox/python_django/venv/lib/python3.9/site-packages/django/db/models/manager.py", line 85, in manager_method
    return getattr(self.get_queryset(), name)(*args, **kwargs)
  File "/home/maria/PycharmProjects/Skillbox/python_django/venv/lib/python3.9/site-packages/django/db/models/query.py", line 650, in get
    raise self.model.DoesNotExist(
django.contrib.auth.models.User.DoesNotExist: User matching query does not exist.
Not Found: /favicon.ico
Internal Server Error: /purchase_confirmed/
Traceback (most recent call last):
  File "/home/maria/PycharmProjects/Skillbox/python_django/venv/lib/python3.9/site-packages/django/core/handlers/exception.py", line 55, in inner
    response = get_response(request)
  File "/home/maria/PycharmProjects/Skillbox/python_django/venv/lib/python3.9/site-packages/django/core/handlers/base.py", line 197, in _get_response
    response = wrapped_callback(request, *callback_args, **callback_kwargs)
  File "/home/maria/PycharmProjects/Skillbox/python_django/12_DjangoCaching/djcaching/app_users/views.py", line 214, in purchase_confirmed_view
    return render(request, 'app_users/purchase_confirmed.html', context={'user_link': user_link,
  File "/home/maria/PycharmProjects/Skillbox/python_django/venv/lib/python3.9/site-packages/django/shortcuts.py", line 24, in render
    content = loader.render_to_string(template_name, context, request, using=using)
  File "/home/maria/PycharmProjects/Skillbox/python_django/venv/lib/python3.9/site-packages/django/template/loader.py", line 62, in render_to_string
    return template.render(context, request)
  File "/home/maria/PycharmProjects/Skillbox/python_django/venv/lib/python3.9/site-packages/django/template/backends/django.py", line 62, in render
    return self.template.render(context)
  File "/home/maria/PycharmProjects/Skillbox/python_django/venv/lib/python3.9/site-packages/django/template/base.py", line 175, in render
    return self._render(context)
  File "/home/maria/PycharmProjects/Skillbox/python_django/venv/lib/python3.9/site-packages/django/test/utils.py", line 111, in instrumented_test_render
    return self.nodelist.render(context)
  File "/home/maria/PycharmProjects/Skillbox/python_django/venv/lib/python3.9/site-packages/django/template/base.py", line 1005, in render
    return SafeString("".join([node.render_annotated(context) for node in self]))
  File "/home/maria/PycharmProjects/Skillbox/python_django/venv/lib/python3.9/site-packages/django/template/base.py", line 1005, in <listcomp>
    return SafeString("".join([node.render_annotated(context) for node in self]))
  File "/home/maria/PycharmProjects/Skillbox/python_django/venv/lib/python3.9/site-packages/django/template/base.py", line 966, in render_annotated
    return self.render(context)
  File "/home/maria/PycharmProjects/Skillbox/python_django/venv/lib/python3.9/site-packages/django/template/loader_tags.py", line 157, in render
    return compiled_parent._render(context)
  File "/home/maria/PycharmProjects/Skillbox/python_django/venv/lib/python3.9/site-packages/django/test/utils.py", line 111, in instrumented_test_render
    return self.nodelist.render(context)
  File "/home/maria/PycharmProjects/Skillbox/python_django/venv/lib/python3.9/site-packages/django/template/base.py", line 1005, in render
    return SafeString("".join([node.render_annotated(context) for node in self]))
  File "/home/maria/PycharmProjects/Skillbox/python_django/venv/lib/python3.9/site-packages/django/template/base.py", line 1005, in <listcomp>
    return SafeString("".join([node.render_annotated(context) for node in self]))
  File "/home/maria/PycharmProjects/Skillbox/python_django/venv/lib/python3.9/site-packages/django/template/base.py", line 966, in render_annotated
    return self.render(context)
  File "/home/maria/PycharmProjects/Skillbox/python_django/venv/lib/python3.9/site-packages/django/template/loader_tags.py", line 157, in render
    return compiled_parent._render(context)
  File "/home/maria/PycharmProjects/Skillbox/python_django/venv/lib/python3.9/site-packages/django/test/utils.py", line 111, in instrumented_test_render
    return self.nodelist.render(context)
  File "/home/maria/PycharmProjects/Skillbox/python_django/venv/lib/python3.9/site-packages/django/template/base.py", line 1005, in render
    return SafeString("".join([node.render_annotated(context) for node in self]))
  File "/home/maria/PycharmProjects/Skillbox/python_django/venv/lib/python3.9/site-packages/django/template/base.py", line 1005, in <listcomp>
    return SafeString("".join([node.render_annotated(context) for node in self]))
  File "/home/maria/PycharmProjects/Skillbox/python_django/venv/lib/python3.9/site-packages/django/template/base.py", line 966, in render_annotated
    return self.render(context)
  File "/home/maria/PycharmProjects/Skillbox/python_django/venv/lib/python3.9/site-packages/django/template/loader_tags.py", line 63, in render
    result = block.nodelist.render(context)
  File "/home/maria/PycharmProjects/Skillbox/python_django/venv/lib/python3.9/site-packages/django/template/base.py", line 1005, in render
    return SafeString("".join([node.render_annotated(context) for node in self]))
  File "/home/maria/PycharmProjects/Skillbox/python_django/venv/lib/python3.9/site-packages/django/template/base.py", line 1005, in <listcomp>
    return SafeString("".join([node.render_annotated(context) for node in self]))
  File "/home/maria/PycharmProjects/Skillbox/python_django/venv/lib/python3.9/site-packages/django/template/base.py", line 966, in render_annotated
    return self.render(context)
  File "/home/maria/PycharmProjects/Skillbox/python_django/venv/lib/python3.9/site-packages/django/template/defaulttags.py", line 193, in render
    values = list(values)
TypeError: 'OrderModel' object is not iterable
Internal Server Error: /purchase_confirmed/
Traceback (most recent call last):
  File "/home/maria/PycharmProjects/Skillbox/python_django/venv/lib/python3.9/site-packages/django/core/handlers/exception.py", line 55, in inner
    response = get_response(request)
  File "/home/maria/PycharmProjects/Skillbox/python_django/venv/lib/python3.9/site-packages/django/core/handlers/base.py", line 197, in _get_response
    response = wrapped_callback(request, *callback_args, **callback_kwargs)
  File "/home/maria/PycharmProjects/Skillbox/python_django/12_DjangoCaching/djcaching/app_users/views.py", line 214, in purchase_confirmed_view
    return render(request, 'app_users/purchase_confirmed.html', context={'user_link': user_link,
  File "/home/maria/PycharmProjects/Skillbox/python_django/venv/lib/python3.9/site-packages/django/shortcuts.py", line 24, in render
    content = loader.render_to_string(template_name, context, request, using=using)
  File "/home/maria/PycharmProjects/Skillbox/python_django/venv/lib/python3.9/site-packages/django/template/loader.py", line 62, in render_to_string
    return template.render(context, request)
  File "/home/maria/PycharmProjects/Skillbox/python_django/venv/lib/python3.9/site-packages/django/template/backends/django.py", line 62, in render
    return self.template.render(context)
  File "/home/maria/PycharmProjects/Skillbox/python_django/venv/lib/python3.9/site-packages/django/template/base.py", line 175, in render
    return self._render(context)
  File "/home/maria/PycharmProjects/Skillbox/python_django/venv/lib/python3.9/site-packages/django/test/utils.py", line 111, in instrumented_test_render
    return self.nodelist.render(context)
  File "/home/maria/PycharmProjects/Skillbox/python_django/venv/lib/python3.9/site-packages/django/template/base.py", line 1005, in render
    return SafeString("".join([node.render_annotated(context) for node in self]))
  File "/home/maria/PycharmProjects/Skillbox/python_django/venv/lib/python3.9/site-packages/django/template/base.py", line 1005, in <listcomp>
    return SafeString("".join([node.render_annotated(context) for node in self]))
  File "/home/maria/PycharmProjects/Skillbox/python_django/venv/lib/python3.9/site-packages/django/template/base.py", line 966, in render_annotated
    return self.render(context)
  File "/home/maria/PycharmProjects/Skillbox/python_django/venv/lib/python3.9/site-packages/django/template/loader_tags.py", line 157, in render
    return compiled_parent._render(context)
  File "/home/maria/PycharmProjects/Skillbox/python_django/venv/lib/python3.9/site-packages/django/test/utils.py", line 111, in instrumented_test_render
    return self.nodelist.render(context)
  File "/home/maria/PycharmProjects/Skillbox/python_django/venv/lib/python3.9/site-packages/django/template/base.py", line 1005, in render
    return SafeString("".join([node.render_annotated(context) for node in self]))
  File "/home/maria/PycharmProjects/Skillbox/python_django/venv/lib/python3.9/site-packages/django/template/base.py", line 1005, in <listcomp>
    return SafeString("".join([node.render_annotated(context) for node in self]))
  File "/home/maria/PycharmProjects/Skillbox/python_django/venv/lib/python3.9/site-packages/django/template/base.py", line 966, in render_annotated
    return self.render(context)
  File "/home/maria/PycharmProjects/Skillbox/python_django/venv/lib/python3.9/site-packages/django/template/loader_tags.py", line 157, in render
    return compiled_parent._render(context)
  File "/home/maria/PycharmProjects/Skillbox/python_django/venv/lib/python3.9/site-packages/django/test/utils.py", line 111, in instrumented_test_render
    return self.nodelist.render(context)
  File "/home/maria/PycharmProjects/Skillbox/python_django/venv/lib/python3.9/site-packages/django/template/base.py", line 1005, in render
    return SafeString("".join([node.render_annotated(context) for node in self]))
  File "/home/maria/PycharmProjects/Skillbox/python_django/venv/lib/python3.9/site-packages/django/template/base.py", line 1005, in <listcomp>
    return SafeString("".join([node.render_annotated(context) for node in self]))
  File "/home/maria/PycharmProjects/Skillbox/python_django/venv/lib/python3.9/site-packages/django/template/base.py", line 966, in render_annotated
    return self.render(context)
  File "/home/maria/PycharmProjects/Skillbox/python_django/venv/lib/python3.9/site-packages/django/template/loader_tags.py", line 63, in render
    result = block.nodelist.render(context)
  File "/home/maria/PycharmProjects/Skillbox/python_django/venv/lib/python3.9/site-packages/django/template/base.py", line 1005, in render
    return SafeString("".join([node.render_annotated(context) for node in self]))
  File "/home/maria/PycharmProjects/Skillbox/python_django/venv/lib/python3.9/site-packages/django/template/base.py", line 1005, in <listcomp>
    return SafeString("".join([node.render_annotated(context) for node in self]))
  File "/home/maria/PycharmProjects/Skillbox/python_django/venv/lib/python3.9/site-packages/django/template/base.py", line 966, in render_annotated
    return self.render(context)
  File "/home/maria/PycharmProjects/Skillbox/python_django/venv/lib/python3.9/site-packages/django/template/defaulttags.py", line 193, in render
    values = list(values)
TypeError: 'OrderModel' object is not iterable
Not Found: /favicon.ico
Not Found: /favicon.ico
Not Found: /favicon.ico
Not Found: /favicon.ico
Internal Server Error: /user_profile/user_1/
Traceback (most recent call last):
  File "/home/maria/PycharmProjects/Skillbox/python_django/venv/lib/python3.9/site-packages/django/core/handlers/exception.py", line 55, in inner
    response = get_response(request)
  File "/home/maria/PycharmProjects/Skillbox/python_django/venv/lib/python3.9/site-packages/django/core/handlers/base.py", line 197, in _get_response
    response = wrapped_callback(request, *callback_args, **callback_kwargs)
  File "/home/maria/PycharmProjects/Skillbox/python_django/12_DjangoCaching/djcaching/app_users/views.py", line 64, in user_profile_view
    user = User.objects.get(username=username)
  File "/home/maria/PycharmProjects/Skillbox/python_django/venv/lib/python3.9/site-packages/django/db/models/manager.py", line 85, in manager_method
    return getattr(self.get_queryset(), name)(*args, **kwargs)
  File "/home/maria/PycharmProjects/Skillbox/python_django/venv/lib/python3.9/site-packages/django/db/models/query.py", line 650, in get
    raise self.model.DoesNotExist(
django.contrib.auth.models.User.DoesNotExist: User matching query does not exist.
Not Found: /favicon.ico
Internal Server Error: /purchase_confirmed/
Traceback (most recent call last):
  File "/home/maria/PycharmProjects/Skillbox/python_django/venv/lib/python3.9/site-packages/django/core/handlers/exception.py", line 55, in inner
    response = get_response(request)
  File "/home/maria/PycharmProjects/Skillbox/python_django/venv/lib/python3.9/site-packages/django/core/handlers/base.py", line 197, in _get_response
    response = wrapped_callback(request, *callback_args, **callback_kwargs)
  File "/home/maria/PycharmProjects/Skillbox/python_django/12_DjangoCaching/djcaching/app_users/views.py", line 214, in purchase_confirmed_view
    return render(request, 'app_users/purchase_confirmed.html', context={'user_link': user_link,
  File "/home/maria/PycharmProjects/Skillbox/python_django/venv/lib/python3.9/site-packages/django/shortcuts.py", line 24, in render
    content = loader.render_to_string(template_name, context, request, using=using)
  File "/home/maria/PycharmProjects/Skillbox/python_django/venv/lib/python3.9/site-packages/django/template/loader.py", line 62, in render_to_string
    return template.render(context, request)
  File "/home/maria/PycharmProjects/Skillbox/python_django/venv/lib/python3.9/site-packages/django/template/backends/django.py", line 62, in render
    return self.template.render(context)
  File "/home/maria/PycharmProjects/Skillbox/python_django/venv/lib/python3.9/site-packages/django/template/base.py", line 175, in render
    return self._render(context)
  File "/home/maria/PycharmProjects/Skillbox/python_django/venv/lib/python3.9/site-packages/django/test/utils.py", line 111, in instrumented_test_render
    return self.nodelist.render(context)
  File "/home/maria/PycharmProjects/Skillbox/python_django/venv/lib/python3.9/site-packages/django/template/base.py", line 1005, in render
    return SafeString("".join([node.render_annotated(context) for node in self]))
  File "/home/maria/PycharmProjects/Skillbox/python_django/venv/lib/python3.9/site-packages/django/template/base.py", line 1005, in <listcomp>
    return SafeString("".join([node.render_annotated(context) for node in self]))
  File "/home/maria/PycharmProjects/Skillbox/python_django/venv/lib/python3.9/site-packages/django/template/base.py", line 966, in render_annotated
    return self.render(context)
  File "/home/maria/PycharmProjects/Skillbox/python_django/venv/lib/python3.9/site-packages/django/template/loader_tags.py", line 157, in render
    return compiled_parent._render(context)
  File "/home/maria/PycharmProjects/Skillbox/python_django/venv/lib/python3.9/site-packages/django/test/utils.py", line 111, in instrumented_test_render
    return self.nodelist.render(context)
  File "/home/maria/PycharmProjects/Skillbox/python_django/venv/lib/python3.9/site-packages/django/template/base.py", line 1005, in render
    return SafeString("".join([node.render_annotated(context) for node in self]))
  File "/home/maria/PycharmProjects/Skillbox/python_django/venv/lib/python3.9/site-packages/django/template/base.py", line 1005, in <listcomp>
    return SafeString("".join([node.render_annotated(context) for node in self]))
  File "/home/maria/PycharmProjects/Skillbox/python_django/venv/lib/python3.9/site-packages/django/template/base.py", line 966, in render_annotated
    return self.render(context)
  File "/home/maria/PycharmProjects/Skillbox/python_django/venv/lib/python3.9/site-packages/django/template/loader_tags.py", line 157, in render
    return compiled_parent._render(context)
  File "/home/maria/PycharmProjects/Skillbox/python_django/venv/lib/python3.9/site-packages/django/test/utils.py", line 111, in instrumented_test_render
    return self.nodelist.render(context)
  File "/home/maria/PycharmProjects/Skillbox/python_django/venv/lib/python3.9/site-packages/django/template/base.py", line 1005, in render
    return SafeString("".join([node.render_annotated(context) for node in self]))
  File "/home/maria/PycharmProjects/Skillbox/python_django/venv/lib/python3.9/site-packages/django/template/base.py", line 1005, in <listcomp>
    return SafeString("".join([node.render_annotated(context) for node in self]))
  File "/home/maria/PycharmProjects/Skillbox/python_django/venv/lib/python3.9/site-packages/django/template/base.py", line 966, in render_annotated
    return self.render(context)
  File "/home/maria/PycharmProjects/Skillbox/python_django/venv/lib/python3.9/site-packages/django/template/loader_tags.py", line 63, in render
    result = block.nodelist.render(context)
  File "/home/maria/PycharmProjects/Skillbox/python_django/venv/lib/python3.9/site-packages/django/template/base.py", line 1005, in render
    return SafeString("".join([node.render_annotated(context) for node in self]))
  File "/home/maria/PycharmProjects/Skillbox/python_django/venv/lib/python3.9/site-packages/django/template/base.py", line 1005, in <listcomp>
    return SafeString("".join([node.render_annotated(context) for node in self]))
  File "/home/maria/PycharmProjects/Skillbox/python_django/venv/lib/python3.9/site-packages/django/template/base.py", line 966, in render_annotated
    return self.render(context)
  File "/home/maria/PycharmProjects/Skillbox/python_django/venv/lib/python3.9/site-packages/django/template/defaulttags.py", line 193, in render
    values = list(values)
TypeError: 'ManyRelatedManager' object is not iterable
Internal Server Error: /purchase_confirmed/
Traceback (most recent call last):
  File "/home/maria/PycharmProjects/Skillbox/python_django/venv/lib/python3.9/site-packages/django/core/handlers/exception.py", line 55, in inner
    response = get_response(request)
  File "/home/maria/PycharmProjects/Skillbox/python_django/venv/lib/python3.9/site-packages/django/core/handlers/base.py", line 197, in _get_response
    response = wrapped_callback(request, *callback_args, **callback_kwargs)
  File "/home/maria/PycharmProjects/Skillbox/python_django/12_DjangoCaching/djcaching/app_users/views.py", line 214, in purchase_confirmed_view
    return render(request, 'app_users/purchase_confirmed.html', context={'user_link': user_link,
  File "/home/maria/PycharmProjects/Skillbox/python_django/venv/lib/python3.9/site-packages/django/shortcuts.py", line 24, in render
    content = loader.render_to_string(template_name, context, request, using=using)
  File "/home/maria/PycharmProjects/Skillbox/python_django/venv/lib/python3.9/site-packages/django/template/loader.py", line 62, in render_to_string
    return template.render(context, request)
  File "/home/maria/PycharmProjects/Skillbox/python_django/venv/lib/python3.9/site-packages/django/template/backends/django.py", line 62, in render
    return self.template.render(context)
  File "/home/maria/PycharmProjects/Skillbox/python_django/venv/lib/python3.9/site-packages/django/template/base.py", line 175, in render
    return self._render(context)
  File "/home/maria/PycharmProjects/Skillbox/python_django/venv/lib/python3.9/site-packages/django/test/utils.py", line 111, in instrumented_test_render
    return self.nodelist.render(context)
  File "/home/maria/PycharmProjects/Skillbox/python_django/venv/lib/python3.9/site-packages/django/template/base.py", line 1005, in render
    return SafeString("".join([node.render_annotated(context) for node in self]))
  File "/home/maria/PycharmProjects/Skillbox/python_django/venv/lib/python3.9/site-packages/django/template/base.py", line 1005, in <listcomp>
    return SafeString("".join([node.render_annotated(context) for node in self]))
  File "/home/maria/PycharmProjects/Skillbox/python_django/venv/lib/python3.9/site-packages/django/template/base.py", line 966, in render_annotated
    return self.render(context)
  File "/home/maria/PycharmProjects/Skillbox/python_django/venv/lib/python3.9/site-packages/django/template/loader_tags.py", line 157, in render
    return compiled_parent._render(context)
  File "/home/maria/PycharmProjects/Skillbox/python_django/venv/lib/python3.9/site-packages/django/test/utils.py", line 111, in instrumented_test_render
    return self.nodelist.render(context)
  File "/home/maria/PycharmProjects/Skillbox/python_django/venv/lib/python3.9/site-packages/django/template/base.py", line 1005, in render
    return SafeString("".join([node.render_annotated(context) for node in self]))
  File "/home/maria/PycharmProjects/Skillbox/python_django/venv/lib/python3.9/site-packages/django/template/base.py", line 1005, in <listcomp>
    return SafeString("".join([node.render_annotated(context) for node in self]))
  File "/home/maria/PycharmProjects/Skillbox/python_django/venv/lib/python3.9/site-packages/django/template/base.py", line 966, in render_annotated
    return self.render(context)
  File "/home/maria/PycharmProjects/Skillbox/python_django/venv/lib/python3.9/site-packages/django/template/loader_tags.py", line 157, in render
    return compiled_parent._render(context)
  File "/home/maria/PycharmProjects/Skillbox/python_django/venv/lib/python3.9/site-packages/django/test/utils.py", line 111, in instrumented_test_render
    return self.nodelist.render(context)
  File "/home/maria/PycharmProjects/Skillbox/python_django/venv/lib/python3.9/site-packages/django/template/base.py", line 1005, in render
    return SafeString("".join([node.render_annotated(context) for node in self]))
  File "/home/maria/PycharmProjects/Skillbox/python_django/venv/lib/python3.9/site-packages/django/template/base.py", line 1005, in <listcomp>
    return SafeString("".join([node.render_annotated(context) for node in self]))
  File "/home/maria/PycharmProjects/Skillbox/python_django/venv/lib/python3.9/site-packages/django/template/base.py", line 966, in render_annotated
    return self.render(context)
  File "/home/maria/PycharmProjects/Skillbox/python_django/venv/lib/python3.9/site-packages/django/template/loader_tags.py", line 63, in render
    result = block.nodelist.render(context)
  File "/home/maria/PycharmProjects/Skillbox/python_django/venv/lib/python3.9/site-packages/django/template/base.py", line 1005, in render
    return SafeString("".join([node.render_annotated(context) for node in self]))
  File "/home/maria/PycharmProjects/Skillbox/python_django/venv/lib/python3.9/site-packages/django/template/base.py", line 1005, in <listcomp>
    return SafeString("".join([node.render_annotated(context) for node in self]))
  File "/home/maria/PycharmProjects/Skillbox/python_django/venv/lib/python3.9/site-packages/django/template/base.py", line 966, in render_annotated
    return self.render(context)
  File "/home/maria/PycharmProjects/Skillbox/python_django/venv/lib/python3.9/site-packages/django/template/defaulttags.py", line 193, in render
    values = list(values)
TypeError: 'ManyRelatedManager' object is not iterable
/home/maria/PycharmProjects/Skillbox/python_django/12_DjangoCaching/djcaching/app_users/views.py changed, reloading.
Watching for file changes with StatReloader
Not Found: /favicon.ico
Not Found: /favicon.ico
Not Found: /favicon.ico
Not Found: /favicon.ico
Internal Server Error: /user_profile/user_1/
Traceback (most recent call last):
  File "/home/maria/PycharmProjects/Skillbox/python_django/venv/lib/python3.9/site-packages/django/core/handlers/exception.py", line 55, in inner
    response = get_response(request)
  File "/home/maria/PycharmProjects/Skillbox/python_django/venv/lib/python3.9/site-packages/django/core/handlers/base.py", line 197, in _get_response
    response = wrapped_callback(request, *callback_args, **callback_kwargs)
  File "/home/maria/PycharmProjects/Skillbox/python_django/12_DjangoCaching/djcaching/app_users/views.py", line 64, in user_profile_view
    user = User.objects.get(username=username)
  File "/home/maria/PycharmProjects/Skillbox/python_django/venv/lib/python3.9/site-packages/django/db/models/manager.py", line 85, in manager_method
    return getattr(self.get_queryset(), name)(*args, **kwargs)
  File "/home/maria/PycharmProjects/Skillbox/python_django/venv/lib/python3.9/site-packages/django/db/models/query.py", line 650, in get
    raise self.model.DoesNotExist(
django.contrib.auth.models.User.DoesNotExist: User matching query does not exist.
Not Found: /favicon.ico
Internal Server Error: /purchase_confirmed/
Traceback (most recent call last):
  File "/home/maria/PycharmProjects/Skillbox/python_django/venv/lib/python3.9/site-packages/django/core/handlers/exception.py", line 55, in inner
    response = get_response(request)
  File "/home/maria/PycharmProjects/Skillbox/python_django/venv/lib/python3.9/site-packages/django/core/handlers/base.py", line 197, in _get_response
    response = wrapped_callback(request, *callback_args, **callback_kwargs)
  File "/home/maria/PycharmProjects/Skillbox/python_django/12_DjangoCaching/djcaching/app_users/views.py", line 212, in purchase_confirmed_view
    for goods in last_order.goods:
TypeError: 'ManyRelatedManager' object is not iterable
Internal Server Error: /purchase_confirmed/
Traceback (most recent call last):
  File "/home/maria/PycharmProjects/Skillbox/python_django/venv/lib/python3.9/site-packages/django/core/handlers/exception.py", line 55, in inner
    response = get_response(request)
  File "/home/maria/PycharmProjects/Skillbox/python_django/venv/lib/python3.9/site-packages/django/core/handlers/base.py", line 197, in _get_response
    response = wrapped_callback(request, *callback_args, **callback_kwargs)
  File "/home/maria/PycharmProjects/Skillbox/python_django/12_DjangoCaching/djcaching/app_users/views.py", line 212, in purchase_confirmed_view
    for goods in last_order.goods:
TypeError: 'ManyRelatedManager' object is not iterable
/home/maria/PycharmProjects/Skillbox/python_django/12_DjangoCaching/djcaching/app_users/views.py changed, reloading.
Watching for file changes with StatReloader
/home/maria/PycharmProjects/Skillbox/python_django/12_DjangoCaching/djcaching/app_users/views.py changed, reloading.
Watching for file changes with StatReloader
Watching for file changes with StatReloader
/home/maria/PycharmProjects/Skillbox/python_django/12_DjangoCaching/djcaching/app_users/models.py changed, reloading.
Watching for file changes with StatReloader
/home/maria/PycharmProjects/Skillbox/python_django/12_DjangoCaching/djcaching/app_users/models.py changed, reloading.
Watching for file changes with StatReloader
/home/maria/PycharmProjects/Skillbox/python_django/12_DjangoCaching/djcaching/app_users/views.py changed, reloading.
Watching for file changes with StatReloader
Not Found: /favicon.ico
Not Found: /favicon.ico
Not Found: /favicon.ico
Not Found: /favicon.ico
Internal Server Error: /user_profile/user_1/
Traceback (most recent call last):
  File "/home/maria/PycharmProjects/Skillbox/python_django/venv/lib/python3.9/site-packages/django/core/handlers/exception.py", line 55, in inner
    response = get_response(request)
  File "/home/maria/PycharmProjects/Skillbox/python_django/venv/lib/python3.9/site-packages/django/core/handlers/base.py", line 197, in _get_response
    response = wrapped_callback(request, *callback_args, **callback_kwargs)
  File "/home/maria/PycharmProjects/Skillbox/python_django/12_DjangoCaching/djcaching/app_users/views.py", line 64, in user_profile_view
    user = User.objects.get(username=username)
  File "/home/maria/PycharmProjects/Skillbox/python_django/venv/lib/python3.9/site-packages/django/db/models/manager.py", line 85, in manager_method
    return getattr(self.get_queryset(), name)(*args, **kwargs)
  File "/home/maria/PycharmProjects/Skillbox/python_django/venv/lib/python3.9/site-packages/django/db/models/query.py", line 650, in get
    raise self.model.DoesNotExist(
django.contrib.auth.models.User.DoesNotExist: User matching query does not exist.
Not Found: /favicon.ico
/home/maria/PycharmProjects/Skillbox/python_django/12_DjangoCaching/djcaching/app_users/views.py changed, reloading.
Watching for file changes with StatReloader
Not Found: /favicon.ico
Not Found: /favicon.ico
Not Found: /favicon.ico
Not Found: /favicon.ico
Internal Server Error: /user_profile/user_1/
Traceback (most recent call last):
  File "/home/maria/PycharmProjects/Skillbox/python_django/venv/lib/python3.9/site-packages/django/core/handlers/exception.py", line 55, in inner
    response = get_response(request)
  File "/home/maria/PycharmProjects/Skillbox/python_django/venv/lib/python3.9/site-packages/django/core/handlers/base.py", line 197, in _get_response
    response = wrapped_callback(request, *callback_args, **callback_kwargs)
  File "/home/maria/PycharmProjects/Skillbox/python_django/12_DjangoCaching/djcaching/app_users/views.py", line 64, in user_profile_view
    user = User.objects.get(username=username)
  File "/home/maria/PycharmProjects/Skillbox/python_django/venv/lib/python3.9/site-packages/django/db/models/manager.py", line 85, in manager_method
    return getattr(self.get_queryset(), name)(*args, **kwargs)
  File "/home/maria/PycharmProjects/Skillbox/python_django/venv/lib/python3.9/site-packages/django/db/models/query.py", line 650, in get
    raise self.model.DoesNotExist(
django.contrib.auth.models.User.DoesNotExist: User matching query does not exist.
Not Found: /favicon.ico
/home/maria/PycharmProjects/Skillbox/python_django/12_DjangoCaching/djcaching/app_users/views.py changed, reloading.
Watching for file changes with StatReloader
Not Found: /favicon.ico
Not Found: /favicon.ico
Not Found: /favicon.ico
Not Found: /favicon.ico
Internal Server Error: /user_profile/user_1/
Traceback (most recent call last):
  File "/home/maria/PycharmProjects/Skillbox/python_django/venv/lib/python3.9/site-packages/django/core/handlers/exception.py", line 55, in inner
    response = get_response(request)
  File "/home/maria/PycharmProjects/Skillbox/python_django/venv/lib/python3.9/site-packages/django/core/handlers/base.py", line 197, in _get_response
    response = wrapped_callback(request, *callback_args, **callback_kwargs)
  File "/home/maria/PycharmProjects/Skillbox/python_django/12_DjangoCaching/djcaching/app_users/views.py", line 64, in user_profile_view
    user = User.objects.get(username=username)
  File "/home/maria/PycharmProjects/Skillbox/python_django/venv/lib/python3.9/site-packages/django/db/models/manager.py", line 85, in manager_method
    return getattr(self.get_queryset(), name)(*args, **kwargs)
  File "/home/maria/PycharmProjects/Skillbox/python_django/venv/lib/python3.9/site-packages/django/db/models/query.py", line 650, in get
    raise self.model.DoesNotExist(
django.contrib.auth.models.User.DoesNotExist: User matching query does not exist.
Not Found: /favicon.ico
/home/maria/PycharmProjects/Skillbox/python_django/12_DjangoCaching/djcaching/app_users/views.py changed, reloading.
Watching for file changes with StatReloader
Not Found: /favicon.ico
Not Found: /favicon.ico
Not Found: /favicon.ico
Not Found: /favicon.ico
Internal Server Error: /user_profile/user_1/
Traceback (most recent call last):
  File "/home/maria/PycharmProjects/Skillbox/python_django/venv/lib/python3.9/site-packages/django/core/handlers/exception.py", line 55, in inner
    response = get_response(request)
  File "/home/maria/PycharmProjects/Skillbox/python_django/venv/lib/python3.9/site-packages/django/core/handlers/base.py", line 197, in _get_response
    response = wrapped_callback(request, *callback_args, **callback_kwargs)
  File "/home/maria/PycharmProjects/Skillbox/python_django/12_DjangoCaching/djcaching/app_users/views.py", line 64, in user_profile_view
    user = User.objects.get(username=username)
  File "/home/maria/PycharmProjects/Skillbox/python_django/venv/lib/python3.9/site-packages/django/db/models/manager.py", line 85, in manager_method
    return getattr(self.get_queryset(), name)(*args, **kwargs)
  File "/home/maria/PycharmProjects/Skillbox/python_django/venv/lib/python3.9/site-packages/django/db/models/query.py", line 650, in get
    raise self.model.DoesNotExist(
django.contrib.auth.models.User.DoesNotExist: User matching query does not exist.
Not Found: /favicon.ico
Not Found: /favicon.ico
Not Found: /favicon.ico
Not Found: /favicon.ico
Not Found: /favicon.ico
Internal Server Error: /user_profile/user_1/
Traceback (most recent call last):
  File "/home/maria/PycharmProjects/Skillbox/python_django/venv/lib/python3.9/site-packages/django/core/handlers/exception.py", line 55, in inner
    response = get_response(request)
  File "/home/maria/PycharmProjects/Skillbox/python_django/venv/lib/python3.9/site-packages/django/core/handlers/base.py", line 197, in _get_response
    response = wrapped_callback(request, *callback_args, **callback_kwargs)
  File "/home/maria/PycharmProjects/Skillbox/python_django/12_DjangoCaching/djcaching/app_users/views.py", line 64, in user_profile_view
    user = User.objects.get(username=username)
  File "/home/maria/PycharmProjects/Skillbox/python_django/venv/lib/python3.9/site-packages/django/db/models/manager.py", line 85, in manager_method
    return getattr(self.get_queryset(), name)(*args, **kwargs)
  File "/home/maria/PycharmProjects/Skillbox/python_django/venv/lib/python3.9/site-packages/django/db/models/query.py", line 650, in get
    raise self.model.DoesNotExist(
django.contrib.auth.models.User.DoesNotExist: User matching query does not exist.
Not Found: /favicon.ico
Not Found: /favicon.ico
Not Found: /favicon.ico
Not Found: /favicon.ico
Not Found: /favicon.ico
Internal Server Error: /user_profile/user_1/
Traceback (most recent call last):
  File "/home/maria/PycharmProjects/Skillbox/python_django/venv/lib/python3.9/site-packages/django/core/handlers/exception.py", line 55, in inner
    response = get_response(request)
  File "/home/maria/PycharmProjects/Skillbox/python_django/venv/lib/python3.9/site-packages/django/core/handlers/base.py", line 197, in _get_response
    response = wrapped_callback(request, *callback_args, **callback_kwargs)
  File "/home/maria/PycharmProjects/Skillbox/python_django/12_DjangoCaching/djcaching/app_users/views.py", line 64, in user_profile_view
    user = User.objects.get(username=username)
  File "/home/maria/PycharmProjects/Skillbox/python_django/venv/lib/python3.9/site-packages/django/db/models/manager.py", line 85, in manager_method
    return getattr(self.get_queryset(), name)(*args, **kwargs)
  File "/home/maria/PycharmProjects/Skillbox/python_django/venv/lib/python3.9/site-packages/django/db/models/query.py", line 650, in get
    raise self.model.DoesNotExist(
django.contrib.auth.models.User.DoesNotExist: User matching query does not exist.
Not Found: /favicon.ico
/home/maria/PycharmProjects/Skillbox/python_django/12_DjangoCaching/djcaching/app_users/models.py changed, reloading.
Watching for file changes with StatReloader
Not Found: /favicon.ico
Not Found: /favicon.ico
Not Found: /favicon.ico
Not Found: /favicon.ico
Internal Server Error: /user_profile/user_1/
Traceback (most recent call last):
  File "/home/maria/PycharmProjects/Skillbox/python_django/venv/lib/python3.9/site-packages/django/core/handlers/exception.py", line 55, in inner
    response = get_response(request)
  File "/home/maria/PycharmProjects/Skillbox/python_django/venv/lib/python3.9/site-packages/django/core/handlers/base.py", line 197, in _get_response
    response = wrapped_callback(request, *callback_args, **callback_kwargs)
  File "/home/maria/PycharmProjects/Skillbox/python_django/12_DjangoCaching/djcaching/app_users/views.py", line 64, in user_profile_view
    user = User.objects.get(username=username)
  File "/home/maria/PycharmProjects/Skillbox/python_django/venv/lib/python3.9/site-packages/django/db/models/manager.py", line 85, in manager_method
    return getattr(self.get_queryset(), name)(*args, **kwargs)
  File "/home/maria/PycharmProjects/Skillbox/python_django/venv/lib/python3.9/site-packages/django/db/models/query.py", line 650, in get
    raise self.model.DoesNotExist(
django.contrib.auth.models.User.DoesNotExist: User matching query does not exist.
Not Found: /favicon.ico
/home/maria/PycharmProjects/Skillbox/python_django/12_DjangoCaching/djcaching/app_users/views.py changed, reloading.
Watching for file changes with StatReloader
/home/maria/PycharmProjects/Skillbox/python_django/12_DjangoCaching/djcaching/app_users/views.py changed, reloading.
Watching for file changes with StatReloader
/home/maria/PycharmProjects/Skillbox/python_django/12_DjangoCaching/djcaching/app_users/views.py changed, reloading.
Watching for file changes with StatReloader
/home/maria/PycharmProjects/Skillbox/python_django/12_DjangoCaching/djcaching/app_users/views.py changed, reloading.
Watching for file changes with StatReloader
/home/maria/PycharmProjects/Skillbox/python_django/12_DjangoCaching/djcaching/app_users/views.py changed, reloading.
Watching for file changes with StatReloader
/home/maria/PycharmProjects/Skillbox/python_django/12_DjangoCaching/djcaching/app_users/views.py changed, reloading.
Watching for file changes with StatReloader
/home/maria/PycharmProjects/Skillbox/python_django/12_DjangoCaching/djcaching/app_users/views.py changed, reloading.
Watching for file changes with StatReloader
/home/maria/PycharmProjects/Skillbox/python_django/12_DjangoCaching/djcaching/app_users/views.py changed, reloading.
Watching for file changes with StatReloader
/home/maria/PycharmProjects/Skillbox/python_django/12_DjangoCaching/djcaching/app_users/views.py changed, reloading.
Watching for file changes with StatReloader
Internal Server Error: /purchase_confirmed/
Traceback (most recent call last):
  File "/home/maria/PycharmProjects/Skillbox/python_django/venv/lib/python3.9/site-packages/django/core/handlers/exception.py", line 55, in inner
    response = get_response(request)
  File "/home/maria/PycharmProjects/Skillbox/python_django/venv/lib/python3.9/site-packages/django/core/handlers/base.py", line 197, in _get_response
    response = wrapped_callback(request, *callback_args, **callback_kwargs)
  File "/home/maria/PycharmProjects/Skillbox/python_django/12_DjangoCaching/djcaching/app_users/views.py", line 210, in purchase_confirmed_view
    print(len(history.orders))
TypeError: object of type 'RelatedManager' has no len()
/home/maria/PycharmProjects/Skillbox/python_django/12_DjangoCaching/djcaching/app_users/views.py changed, reloading.
Watching for file changes with StatReloader
/home/maria/PycharmProjects/Skillbox/python_django/12_DjangoCaching/djcaching/app_users/views.py changed, reloading.
Watching for file changes with StatReloader
/home/maria/PycharmProjects/Skillbox/python_django/12_DjangoCaching/djcaching/app_users/views.py changed, reloading.
Watching for file changes with StatReloader
/home/maria/PycharmProjects/Skillbox/python_django/12_DjangoCaching/djcaching/app_users/views.py changed, reloading.
Watching for file changes with StatReloader
/home/maria/PycharmProjects/Skillbox/python_django/12_DjangoCaching/djcaching/app_users/views.py changed, reloading.
Watching for file changes with StatReloader
/home/maria/PycharmProjects/Skillbox/python_django/12_DjangoCaching/djcaching/app_users/views.py changed, reloading.
Watching for file changes with StatReloader
/home/maria/PycharmProjects/Skillbox/python_django/12_DjangoCaching/djcaching/app_users/views.py changed, reloading.
Watching for file changes with StatReloader
/home/maria/PycharmProjects/Skillbox/python_django/12_DjangoCaching/djcaching/app_users/views.py changed, reloading.
Watching for file changes with StatReloader
/home/maria/PycharmProjects/Skillbox/python_django/12_DjangoCaching/djcaching/app_users/models.py changed, reloading.
Watching for file changes with StatReloader
Watching for file changes with StatReloader
/home/maria/PycharmProjects/Skillbox/python_django/12_DjangoCaching/djcaching/app_users/views.py changed, reloading.
Watching for file changes with StatReloader
/home/maria/PycharmProjects/Skillbox/python_django/12_DjangoCaching/djcaching/app_users/views.py changed, reloading.
Watching for file changes with StatReloader
/home/maria/PycharmProjects/Skillbox/python_django/12_DjangoCaching/djcaching/app_users/views.py changed, reloading.
Watching for file changes with StatReloader
/home/maria/PycharmProjects/Skillbox/python_django/12_DjangoCaching/djcaching/app_users/views.py changed, reloading.
Watching for file changes with StatReloader
/home/maria/PycharmProjects/Skillbox/python_django/12_DjangoCaching/djcaching/app_users/__init__.py changed, reloading.
Watching for file changes with StatReloader
Not Found: /favicon.ico
Not Found: /favicon.ico
Not Found: /favicon.ico
Not Found: /favicon.ico
Not Found: /favicon.ico
Not Found: /favicon.ico
Not Found: /favicon.ico
Not Found: /favicon.ico
Not Found: /favicon.ico
Not Found: /favicon.ico
Not Found: /favicon.ico
Not Found: /favicon.ico
Watching for file changes with StatReloader
Not Found: /favicon.ico
Not Found: /favicon.ico
Not Found: /favicon.ico
/home/maria/PycharmProjects/Skillbox/python_django/12_DjangoCaching/djcaching/app_users/views.py changed, reloading.
Watching for file changes with StatReloader
/home/maria/PycharmProjects/Skillbox/python_django/12_DjangoCaching/djcaching/app_users/__init__.py changed, reloading.
Watching for file changes with StatReloader
Not Found: /favicon.ico
/home/maria/PycharmProjects/Skillbox/python_django/12_DjangoCaching/djcaching/djcaching/settings.py changed, reloading.
Watching for file changes with StatReloader
Watching for file changes with StatReloader
Not Found: /favicon.ico
Пользователь {user.username} зашёл на сайт
/home/maria/PycharmProjects/Skillbox/python_django/12_DjangoCaching/djcaching/app_users/__init__.py changed, reloading.
Watching for file changes with StatReloader
Not Found: /favicon.ico
Пользователь admin зашёл на сайт
Watching for file changes with StatReloader
/home/maria/PycharmProjects/Skillbox/python_django/12_DjangoCaching/djcaching/djcaching/settings.py changed, reloading.
Watching for file changes with StatReloader
/home/maria/PycharmProjects/Skillbox/python_django/12_DjangoCaching/djcaching/djcaching/settings.py changed, reloading.
Watching for file changes with StatReloader
Watching for file changes with StatReloader
Not Found: /favicon.ico
Watching for file changes with StatReloader
Watching for file changes with StatReloader
Not Found: /favicon.ico
Not Found: /favicon.ico
Not Found: /favicon.ico
Not Found: /favicon.ico
Произведено пополнение счёта на 1000.0
Произведено пополнение счёта на 0.0
Internal Server Error: /user_profile/user_1/
Traceback (most recent call last):
  File "/home/maria/PycharmProjects/Django learning/Webstore_app/venv/lib/python3.9/site-packages/django/core/handlers/exception.py", line 55, in inner
    response = get_response(request)
  File "/home/maria/PycharmProjects/Django learning/Webstore_app/venv/lib/python3.9/site-packages/django/core/handlers/base.py", line 197, in _get_response
    response = wrapped_callback(request, *callback_args, **callback_kwargs)
  File "/home/maria/PycharmProjects/Django learning/Webstore_app/djcaching/app_users/views.py", line 66, in user_profile_view
    user = User.objects.get(username=username)
  File "/home/maria/PycharmProjects/Django learning/Webstore_app/venv/lib/python3.9/site-packages/django/db/models/manager.py", line 85, in manager_method
    return getattr(self.get_queryset(), name)(*args, **kwargs)
  File "/home/maria/PycharmProjects/Django learning/Webstore_app/venv/lib/python3.9/site-packages/django/db/models/query.py", line 650, in get
    raise self.model.DoesNotExist(
django.contrib.auth.models.User.DoesNotExist: User matching query does not exist.
Not Found: /favicon.ico
Пользователь user_1 зашёл на сайт
Пользователь user_1 зашёл на сайт
Пользователь user_1 зашёл на сайт
Пользователь user_1 зашёл на сайт
Пользователь user_1 зашёл на сайт
Пользователь user_1 зашёл на сайт
Пользователь user_1 зашёл на сайт
Пользователь user_1 зашёл на сайт
Пользователь user_1 потратил 1000.0 средств
Ползователь сделал заказ Дата покупки: 2023-01-30 12:25:27.522515+00:00
Название: A fine goods
Цена: 1000.0
Магазин: test_shop_1
Артикул: 123456

Пользователь user_1 потратил 1000.0 средств
Пользователь user_1 зашёл на сайт
Пользователь user_1 зашёл на сайт
Ползователь сделал заказ Дата покупки: 2023-01-30 12:25:27.550648+00:00
Название: A fine goods
Цена: 1000.0
Магазин: test_shop_1
Артикул: 123456

Пользователь user_1 получил статус UserStatusModel object (2)
Пользователь user_1 потратил 2000.0 средств
Пользователь user_1 зашёл на сайт
Пользователь user_1 зашёл на сайт
Пользователь user_1 зашёл на сайт
Пользователь user_1 зашёл на сайт
Пользователь user_1 зашёл на сайт
Пользователь user_1 зашёл на сайт
Пользователь user_1 зашёл на сайт
Пользователь user_1 зашёл на сайт
Пользователь user_1 зашёл на сайт
Пользователь user_1 зашёл на сайт
Пользователь user_1 зашёл на сайт
Пользователь user_1 зашёл на сайт
Пользователь user_1 зашёл на сайт
Пользователь user_1 зашёл на сайт
Пользователь user_1 зашёл на сайт
Пользователь user_1 зашёл на сайт
Ползователь сделал заказ Дата покупки: 2023-01-30 12:25:28.059443+00:00
Название: A fine goods
Цена: 1000.0
Магазин: test_shop_1
Артикул: 123456

Пользователь user_1 зашёл на сайт
Пользователь user_1 зашёл на сайт
Ползователь сделал заказ Дата покупки: 2023-01-30 12:25:28.040352+00:00
Название: A fine goods
Цена: 1000.0
Магазин: test_shop_1
Артикул: 123456
Название: Another fine goods
Цена: 1500.0
Магазин: test_shop_1
Артикул: 123465

Пользователь user_1 зашёл на сайт
Пользователь user_1 зашёл на сайт
Ползователь сделал заказ Дата покупки: 2023-01-30 12:25:28.040352+00:00
Название: A fine goods
Цена: 1000.0
Магазин: test_shop_1
Артикул: 123456
Название: Another fine goods
Цена: 1500.0
Магазин: test_shop_1
Артикул: 123465

Пользователь user_1 зашёл на сайт
Пользователь user_1 зашёл на сайт
Пользователь user_1 зашёл на сайт
Пользователь user_1 зашёл на сайт
Ползователь сделал заказ Дата покупки: 2023-01-30 12:25:28.040352+00:00
Название: A fine goods
Цена: 1000.0
Магазин: test_shop_1
Артикул: 123456
Название: Another fine goods
Цена: 1500.0
Магазин: test_shop_1
Артикул: 123465

Пользователь user_1 зашёл на сайт
Пользователь user_1 зашёл на сайт
Пользователь user_1 зашёл на сайт
Пользователь user_1 зашёл на сайт
Пользователь user_1 зашёл на сайт
Пользователь user_1 зашёл на сайт
Пользователь user_1 зашёл на сайт
Пользователь user_1 зашёл на сайт
Пользователь user_1 зашёл на сайт
Пользователь user_1 зашёл на сайт
Пользователь user_1 зашёл на сайт
Пользователь user_1 зашёл на сайт
Пользователь user_1 зашёл на сайт
Пользователь user_1 зашёл на сайт
